Workbook

Sheet Lectura
A1: ¿El negocio da o no da? Lectura con los números a la vista
A2: Cota optimista: los costos sin dato (alquiler de la casa, luz, gas y agua, contador, pileta, cabinas) están en 0 o en un piso. Precios: lista de la zona cercana (Ambrela). USD constantes sin IVA.
A4: Indicador | B4: Conservador | C4: Base | D4: Favorable | E4: Cómo se lee
A5: Precio neto promedio por miembro flex (USD por mes, sin IVA) | B5: =Equilibrio!B5 -> 40.911952 | C5: =Equilibrio!C5 -> 46.972982 | D5: =Equilibrio!D5 -> 50.382311 | E5: Mezcla de planes con el precio de la zona, menos descuento, sin IVA.
A6: Miembros flex necesarios para cubrir los costos | B6: =Equilibrio!B11 -> 204.61133 | C6: =Equilibrio!C11 -> 77.930628 | D6: =Equilibrio!D11 -> 31.457124 | E6: En régimen (mes 36).
A7: Tope de miembros flex que entran en los puestos | B7: =Equilibrio!B12 -> 45.561793 | C7: =Equilibrio!C12 -> 60.325567 | D7: =Equilibrio!D12 -> 78.074689 | E7: Puestos simultáneos, con el pico de martes a jueves.
A8: El equilibrio necesita este % del tope | B8: =Equilibrio!B13 -> 4.4908534 | C8: =Equilibrio!C13 -> 1.2918342 | D8: =Equilibrio!D13 -> 0.40291065 | E8: Más de 100 %: no alcanza ni con todos los puestos llenos.
A9: Resultado operativo mensual con todos los puestos llenos (mejor caso) | B9: =Equilibrio!B12*Equilibrio!B8+Equilibrio!B10-Equilibrio!B9 -> -3604.4912 | C9: =Equilibrio!C12*Equilibrio!C8+Equilibrio!C10-Equilibrio!C9 -> -618.15699 | D9: =Equilibrio!D12*Equilibrio!D8+Equilibrio!D10-Equilibrio!D9 -> 2054.3494 | E9: Si es negativo, el negocio pierde plata aunque se llene.
A10: Resultado operativo mensual en el mes 36 (con las altas supuestas) | B10: =Resumen!B11 -> -4343.6254 | C10: =Resumen!C11 -> -1603.6953 | D10: =Resumen!D11 -> 1078.5811 | E10: Antes de Ganancias y sin alquilar la casa.
A11: Inversión inicial (sin capital de trabajo) | B11: =Resumen!B5 -> 275790.19 | C11: =Resumen!C5 -> 197524.94 | D11: =Resumen!D5 -> 135685.4 | E11: Obra, equipamiento, honorarios, trámites y contingencias.
A12: Años para recuperar la inversión con todos los puestos llenos | B12: =IF(B9>0,B11/(B9*12),"no la recupera") -> no la recupera | C12: =IF(C9>0,C11/(C9*12),"no la recupera") -> no la recupera | D12: =IF(D9>0,D11/(D9*12),"no la recupera") -> 5.5039893 | E12: Inversión / (mejor caso × 12).
A13: Precio necesario para equilibrar con el 80 % del tope (veces el precio del escenario) | B13: =(Equilibrio!B9+0.8*Equilibrio!B12*(Equilibrio!B7-Equilibrio!B5*((1+Supuestos!$D$7*Supuestos!$D$8)*(Supuestos!$D$54+Supuestos!$D$56)+Supuestos!$D$55)))/(0.8*Equilibrio!B12*Equilibrio!B5*(1-((1+Supuestos!$D$7*Supuestos!$D$8)*(Supuestos!$D$54+Supuestos!$D$56)+Supuestos!$D$55))+Equilibrio!B10) -> 3.1829985 | C13: =(Equilibrio!C9+0.8*Equilibrio!C12*(Equilibrio!C7-Equilibrio!C5*((1+Supuestos!$E$7*Supuestos!$E$8)*(Supuestos!$E$54+Supuestos!$E$56)+Supuestos!$E$55)))/(0.8*Equilibrio!C12*Equilibrio!C5*(1-((1+Supuestos!$E$7*Supuestos!$E$8)*(Supuestos!$E$54+Supuestos!$E$56)+Supuestos!$E$55))+Equilibrio!C10) -> 1.3382453 | D13: =(Equilibrio!D9+0.8*Equilibrio!D12*(Equilibrio!D7-Equilibrio!D5*((1+Supuestos!$F$7*Supuestos!$F$8)*(Supuestos!$F$54+Supuestos!$F$56)+Supuestos!$F$55)))/(0.8*Equilibrio!D12*Equilibrio!D5*(1-((1+Supuestos!$F$7*Supuestos!$F$8)*(Supuestos!$F$54+Supuestos!$F$56)+Supuestos!$F$55))+Equilibrio!D10) -> 0.71522535 | E13: 1,00 = los precios de hoy; 2,00 = el doble.
A14: Plan de 12 días por mes necesario para equilibrar al 80 % (ARS con IVA) | B14: =B13*Supuestos!$D$27*Supuestos!$D$37 -> 295063.96 | C14: =C13*Supuestos!$E$27*Supuestos!$E$37 -> 137839.27 | D14: =D13*Supuestos!$F$27*Supuestos!$F$37 -> 77351.622 | E14: Comparar con Ambrela 3 días/sem (103.000) y HUERTA 12 días (302.500 con IVA), ver hoja Mercado_verificado.
A15: Mejor caso si el dueño atiende y no hay personal pago (USD por mes) | B15: =B9+Modelo_Conservador!AM30*(1+Supuestos!$D$69) -> -1725.9392 | C15: =C9+Modelo_Base!AM30*(1+Supuestos!$E$69) -> 1121.903 | D15: =D9+Modelo_Favorable!AM30*(1+Supuestos!$F$69) -> 3707.9419 | E15: Suma el sueldo y las cargas que se ahorran (con el % de imprevistos). El tiempo del dueño no está valorado.
A16: Años para recuperar la inversión en ese caso | B16: =IF(B15>0,B11/(B15*12),"no la recupera") -> no la recupera | C16: =IF(C15>0,C11/(C15*12),"no la recupera") -> 14.671867 | D16: =IF(D15>0,D11/(D15*12),"no la recupera") -> 3.0494321 | E16: Inversión / (resultado × 12), con todos los puestos llenos.
A17: VEREDICTO (cota optimista) | B17: =IF(B9<0,"NO DA",IF(B8>0.8,"AJUSTADO",IF(B12>5,"SOLO OPERATIVO","DA"))) -> NO DA | C17: =IF(C9<0,"NO DA",IF(C8>0.8,"AJUSTADO",IF(C12>5,"SOLO OPERATIVO","DA"))) -> NO DA | D17: =IF(D9<0,"NO DA",IF(D8>0.8,"AJUSTADO",IF(D12>5,"SOLO OPERATIVO","DA"))) -> SOLO OPERATIVO | E17: NO DA = aun lleno no cubre los costos · AJUSTADO = necesita más del 80 % del tope · SOLO OPERATIVO = cubre los costos pero la inversión tarda más de 5 años en volver · DA = cubre y recupera en 5 años o menos.
A19: Aparte, NO verificado y fuera del modelo: elburó (Villa Urquiza, ficha probable) publica Flex 'desde' ARS 115.000 y puesto fijo ARS 257.000 a 300.000, sin fecha ni IVA (datos/sedes_G3.json, G3-01). Si se confirmara, sugiere precios cerca de 30 % más altos que Ambrela en planes flex.

Sheet Resumen
A1: Resumen por escenario
A2: Todo se recalcula al cambiar Supuestos. USD constantes; resultado antes del impuesto a las Ganancias.
A4: Indicador | B4: Conservador | C4: Base | D4: Favorable | E4: Cómo se lee
A5: Inversión inicial (sin capital de trabajo) | B5: =Inversion!D21 -> 275790.19 | C5: =Inversion!E21 -> 197524.94 | D5: =Inversion!F21 -> 135685.4 | E5: Obra, equipamiento, honorarios, trámites, apertura y contingencias.
A6: Necesidad máxima de caja (inversión + pérdidas de arranque) | B6: =-MIN(Modelo_Conservador!C45:AM45) -> 434690.54 | C6: =-MIN(Modelo_Base!C45:AM45) -> 265076 | D6: =-MIN(Modelo_Favorable!C45:AM45) -> 141419.64 | E6: Lo que hay que tener disponible en el peor momento del flujo acumulado.
A7: Miembros flex en el mes 12 | B7: =Modelo_Conservador!O7 -> 15.80834 | C7: =Modelo_Base!O7 -> 28.583586 | D7: =Modelo_Favorable!O7 -> 46.06943
A8: Miembros flex en el mes 36 | B8: =Modelo_Conservador!AM7 -> 12.947217 | C8: =Modelo_Base!AM7 -> 32.257515 | D8: =Modelo_Favorable!AM7 -> 55.932426 | E8: Limitado por el tope de puestos en el pico.
A9: Ocupación promedio de puestos flex, mes 36 | B9: =Modelo_Conservador!AM12 -> 0.21049503 | C9: =Modelo_Base!AM12 -> 0.41132598 | D9: =Modelo_Favorable!AM12 -> 0.57311712 | E9: Puestos-día usados / puestos-día disponibles en días hábiles.
A10: Ingresos del mes 36 (USD sin IVA) | B10: =Modelo_Conservador!AM21 -> 1336.8161 | C10: =Modelo_Base!AM21 -> 2828.8044 | D10: =Modelo_Favorable!AM21 -> 4875.8085
A11: Resultado operativo del mes 36 | B11: =Modelo_Conservador!AM42 -> -4343.6254 | C11: =Modelo_Base!AM42 -> -1603.6953 | D11: =Modelo_Favorable!AM42 -> 1078.5811
A12: Resultado operativo acumulado de los 36 meses | B12: =SUM(Modelo_Conservador!D42:AM42) -> -158900.36 | C12: =SUM(Modelo_Base!D42:AM42) -> -67551.058 | D12: =SUM(Modelo_Favorable!D42:AM42) -> 18897.552
A13: Margen operativo del año 3 | B13: =IFERROR(SUM(Modelo_Conservador!AB42:AM42)/SUM(Modelo_Conservador!AB21:AM21),0) -> -3.2157883 | C13: =IFERROR(SUM(Modelo_Base!AB42:AM42)/SUM(Modelo_Base!AB21:AM21),0) -> -0.57727416 | D13: =IFERROR(SUM(Modelo_Favorable!AB42:AM42)/SUM(Modelo_Favorable!AB21:AM21),0) -> 0.21154443 | E13: Resultado operativo / ingresos, meses 25 a 36.
A14: Mes de recupero de la inversión (caja, casa propia) | B14: =IFERROR(MATCH(TRUE(),INDEX(Modelo_Conservador!C45:AM45>=0,0),0)-1,"no recupera en 36 meses") -> no recupera en 36 meses | C14: =IFERROR(MATCH(TRUE(),INDEX(Modelo_Base!C45:AM45>=0,0),0)-1,"no recupera en 36 meses") -> no recupera en 36 meses | D14: =IFERROR(MATCH(TRUE(),INDEX(Modelo_Favorable!C45:AM45>=0,0),0)-1,"no recupera en 36 meses") -> no recupera en 36 meses | E14: Primer mes con flujo acumulado ≥ 0.
A15: Mes de recupero frente a alquilar la casa | B15: =IFERROR(MATCH(TRUE(),INDEX(Modelo_Conservador!C48:AM48>=0,0),0)-1,"no recupera en 36 meses") -> no recupera en 36 meses | C15: =IFERROR(MATCH(TRUE(),INDEX(Modelo_Base!C48:AM48>=0,0),0)-1,"no recupera en 36 meses") -> no recupera en 36 meses | D15: =IFERROR(MATCH(TRUE(),INDEX(Modelo_Favorable!C48:AM48>=0,0),0)-1,"no recupera en 36 meses") -> no recupera en 36 meses | E15: Igual, restando cada mes el alquiler que se deja de cobrar.
A16: TIR anual a 36 meses, sin valor residual (caja) | B16: =IFERROR((1+IRR(Modelo_Conservador!C44:AM44))^12-1,"no calculable") -> no calculable | C16: =IFERROR((1+IRR(Modelo_Base!C44:AM44))^12-1,"no calculable") -> no calculable | D16: =IFERROR((1+IRR(Modelo_Favorable!C44:AM44))^12-1,"no calculable") -> no calculable | E16: Conservadora: no suma lo que vale el negocio ni el equipamiento al mes 36.
A17: VAN a 36 meses con la tasa de Supuestos (caja) | B17: =NPV((1+Supuestos!$D$92)^(1/12)-1,Modelo_Conservador!D44:AM44)+Modelo_Conservador!C44+Supuestos!$D$93/(1+Supuestos!$D$92)^3 -> -410246.25 | C17: =NPV((1+Supuestos!$E$92)^(1/12)-1,Modelo_Base!D44:AM44)+Modelo_Base!C44+Supuestos!$E$93/(1+Supuestos!$E$92)^3 -> -255543.63 | D17: =NPV((1+Supuestos!$F$92)^(1/12)-1,Modelo_Favorable!D44:AM44)+Modelo_Favorable!C44+Supuestos!$F$93/(1+Supuestos!$F$92)^3 -> -121557.68 | E17: La tasa la define el inversor; el valor que viene es un supuesto.
A18: Alquiler de mercado de la casa que se deja de cobrar (por mes) | B18: =Supuestos!$D$91 -> 0 | C18: =Supuestos!$E$91 -> 0 | D18: =Supuestos!$F$91 -> 0 | E18: Costo de oportunidad de usar la casa propia.
A19: Resultado operativo del año 3 menos el alquiler que se deja de cobrar (por mes) | B19: =AVERAGE(Modelo_Conservador!AB42:AM42)-Supuestos!$D$91 -> -4337.0558 | C19: =AVERAGE(Modelo_Base!AB42:AM42)-Supuestos!$E$91 -> -1620.228 | D19: =AVERAGE(Modelo_Favorable!AB42:AM42)-Supuestos!$F$91 -> 1016.415 | E19: Si es negativo, alquilar la casa rinde más que el coworking (antes de impuestos).

Sheet Supuestos
A1: Supuestos del modelo (celdas azules = entradas editables)
A2: Marco monetario: USD constantes al 27/10/2026. TC de conversión de precios en pesos: ver fila 'tc'. Sin previsiones de inflación ni devaluación. Cada valor tiene su fuente o se marca como supuesto a validar.
A4: Clave | B4: Supuesto | C4: Unidad | D4: Conservador | E4: Base | F4: Favorable | G4: Fuente / justificación | H4: Tipo
A5: GENERALES
A6: tc | B6: Tipo de cambio para pasar pesos a dólares | C6: ARS por USD | D6: 1560 | E6: 1560 | F6: 1560 | G6: dolarapi.com, dólar oficial BNA venta, 27/10/2026 (datos/alquiler_oficinas.json). | H6: dato
A7: iva | B7: Alícuota de IVA | C7: % | D7: 0.21 | E7: 0.21 | F7: 0.21 | G7: Ley de IVA, alícuota general. | H7: dato
A8: ri | B8: ¿Responsable inscripto? (1 = sí, 0 = monotributo) | C8: 1/0 | D8: 1 | E8: 1 | F8: 1 | G8: Monotributo no alcanza: tope de 200 m² para locaciones/servicios (LEEME); se asume Responsable Inscripto. A confirmar con contador. | H8: supuesto
A9: dias_habiles | B9: Días hábiles por mes | C9: días | D9: 21 | E9: 21 | F9: 21 | G9: Promedio de lunes a viernes sin feriados nacionales (aprox.). | H9: supuesto
A10: meses_obra | B10: Meses de obra y habilitación antes de abrir | C10: meses | D10: 6 | E10: 4 | F10: 3 | G10: Supuesto a validar con el arquitecto y el gestor. | H10: a validar
A11: CAPACIDAD (casa de 450 m²: subsuelo, planta baja + patio, planta alta; distribución sin plano)
A12: puestos_flex | B12: Puestos flexibles (simultáneos) | C12: puestos | D12: 30 | E12: 36 | F12: 42 | G12: SUPUESTO sin plano ni dato en el repo: 7,5 a 11 m² totales por puesto (incluye baños, cocina, salas, circulación y escalera). El coeficiente de ocupación del Código (Art. 3.4.7.2) no se pudo verificar (entorno_y_normativa.md, 2.3). | H12: a validar
A13: puestos_fijos | B13: Puestos fijos (escritorio asignado) | C13: puestos | D13: 4 | E13: 6 | F13: 8 | G13: SUPUESTO sin plano ni dato en el repo: 7,5 a 11 m² totales por puesto (incluye baños, cocina, salas, circulación y escalera). El coeficiente de ocupación del Código (Art. 3.4.7.2) no se pudo verificar (entorno_y_normativa.md, 2.3). | H13: a validar
A14: oficinas_priv | B14: Oficinas privadas chicas (complemento) | C14: oficinas | D14: 2 | E14: 2 | F14: 3 | G14: SUPUESTO sin plano ni dato en el repo: 7,5 a 11 m² totales por puesto (incluye baños, cocina, salas, circulación y escalera). El coeficiente de ocupación del Código (Art. 3.4.7.2) no se pudo verificar (entorno_y_normativa.md, 2.3). | H14: a validar
A15: puestos_por_oficina | B15: Puestos por oficina privada | C15: puestos | D15: 3 | E15: 3 | F15: 3 | G15: Oficina de 3 personas (aprox. 12–15 m²). | H15: supuesto
A16: USO DE LOS PUESTOS
A17: uso_flex | B17: Uso real de los días incluidos (flex) | C17: % | D17: 0.85 | E17: 0.8 | F17: 0.75 | G17: Mayor uso = menos membresías por puesto (por eso el conservador usa el más alto). Supuesto a medir en la preventa. | H17: a validar
A18: factor_pico | B18: Pico de asistencia sobre el promedio (mar-jue) | C18: veces | D18: 1.35 | E18: 1.3 | F18: 1.25 | G18: Los coworkings se llenan martes a jueves; supuesto a medir. | H18: a validar
A19: uso_fijo | B19: Uso de los puestos fijos y oficinas (para consumo) | C19: % | D19: 0.8 | E19: 0.8 | F19: 0.8 | G19: Supuesto. | H19: supuesto
A20: PLANES Y PRECIOS (ARS por mes, con IVA, como se publican)
A21: dias_p1 | B21: Plan 4 días por mes: días incluidos | C21: días/mes | D21: 4 | E21: 4 | F21: 4 | G21: Diseño de la oferta propuesta. | H21: supuesto
A22: dias_p2 | B22: Plan 8 días por mes (≈2 por semana): días incluidos | C22: días/mes | D22: 8 | E22: 8 | F22: 8 | G22: Diseño de la oferta propuesta. | H22: supuesto
A23: dias_p3 | B23: Plan 12 días por mes (≈3 por semana): días incluidos | C23: días/mes | D23: 12 | E23: 12 | F23: 12 | G23: Diseño de la oferta propuesta. | H23: supuesto
A24: dias_p4 | B24: Plan ilimitado flex (lunes a viernes): días incluidos | C24: días/mes | D24: 21 | E24: 21 | F24: 21 | G24: Diseño de la oferta propuesta. | H24: supuesto
A25: precio_p1 | B25: Precio plan 1 | C25: ARS/mes | D25: 54900 | E25: 54900 | F25: 54900 | G25: DERIVADO, no publicado: Ambrela no vende plan de 4 días. Precio del plan 2 días/sem (89.000) × proporción 4D/8D de HUERTA (135.000/219.000). | H25: mercado
A26: precio_p2 | B26: Precio plan 2 | C26: ARS/mes | D26: 89000 | E26: 89000 | F26: 89000 | G26: Ambrela (Devoto, 3,6 km; único competidor directo), datos/sedes_G1A.json G1A-01: precio publicado sin fecha ni IVA aclarado y sin moneda explícita (se asume ARS por magnitud, sin confirmar); se toma como precio final. Plan 'Start Point 2 Días' (≈ 8-9 días por mes). | H26: mercado
A27: precio_p3 | B27: Precio plan 3 | C27: ARS/mes | D27: 103000 | E27: 103000 | F27: 103000 | G27: Ambrela (Devoto, 3,6 km; único competidor directo), datos/sedes_G1A.json G1A-01: precio publicado sin fecha ni IVA aclarado y sin moneda explícita (se asume ARS por magnitud, sin confirmar); se toma como precio final. Plan 'Start Point 3 Días' (≈ 13 días por mes). | H27: mercado
A28: precio_p4 | B28: Precio plan 4 | C28: ARS/mes | D28: 111200 | E28: 111200 | F28: 111200 | G28: DERIVADO, no publicado: Ambrela no vende ilimitado flex. Precio 3 días/sem (103.000) × proporción FLEX/12D de HUERTA (270.000/250.000); queda bajo el puesto fijo de Ambrela (118.000). | H28: mercado
A29: mix_p1 | B29: Peso del plan 1 en los miembros flex | C29: % | D29: 0.1 | E29: 0.1 | F29: 0.1 | G29: SUPUESTO sin dato: en la zona solo Ambrela publica planes (2 y 3 días por semana y puesto fijo). Medir en la preventa. | H29: a validar
A30: mix_p2 | B30: Peso del plan 2 en los miembros flex | C30: % | D30: 0.35 | E30: 0.35 | F30: 0.35 | G30: SUPUESTO sin dato: en la zona solo Ambrela publica planes (2 y 3 días por semana y puesto fijo). Medir en la preventa. | H30: a validar
A31: mix_p3 | B31: Peso del plan 3 en los miembros flex | C31: % | D31: 0.3 | E31: 0.3 | F31: 0.3 | G31: SUPUESTO sin dato: en la zona solo Ambrela publica planes (2 y 3 días por semana y puesto fijo). Medir en la preventa. | H31: a validar
A32: mix_p4 | B32: Peso del plan 4 en los miembros flex | C32: % | D32: 0.25 | E32: 0.25 | F32: 0.25 | G32: SUPUESTO sin dato: en la zona solo Ambrela publica planes (2 y 3 días por semana y puesto fijo). Medir en la preventa. | H32: a validar
... A43: ramp_of | B43: Meses hasta ocupar las oficinas privadas | C43: meses | D43: 10 | E43: 6 | F43: 4 | G43: Supuesto. | H43: a validar
A44: ALTAS Y BAJAS DE MIEMBROS FLEX
A45: miembros_ini | B45: Miembros al abrir (preventa / lista de espera) | C45: miembros | D45: 0 | E45: 5 | F45: 10 | G45: Depende de la preventa (ver plan de validación). | H45: a validar
A46: altas_f1 | B46: Altas por mes, meses 1 a 6 | C46: miembros/mes | D46: 2 | E46: 3 | F46: 5 | G46: SUPUESTO sin dato de demanda: ningún archivo del repo mide cuántos profesionales de la zona usarían un coworking (entorno_y_normativa.md, 4). Medir con preventa y lista de espera. | H46: a validar
A47: altas_f2 | B47: Altas por mes, meses 7 a 12 | C47: miembros/mes | D47: 2 | E47: 3 | F47: 4 | G47: SUPUESTO sin dato de demanda: ningún archivo del repo mide cuántos profesionales de la zona usarían un coworking (entorno_y_normativa.md, 4). Medir con preventa y lista de espera. | H47: a validar
A48: altas_f3 | B48: Altas por mes, meses 13 a 36 | C48: miembros/mes | D48: 1 | E48: 2 | F48: 3 | G48: SUPUESTO sin dato de demanda: ningún archivo del repo mide cuántos profesionales de la zona usarían un coworking (entorno_y_normativa.md, 4). Medir con preventa y lista de espera. | H48: a validar
A49: churn | B49: Bajas mensuales de miembros flex | C49: % | D49: 0.08 | E49: 0.06 | F49: 0.05 | G49: SUPUESTO sin dato local. | H49: a validar
A50: altas_fijo | B50: Altas de puestos fijos por mes | C50: puestos/mes | D50: 0.5 | E50: 1 | F50: 1.5 | G50: Supuesto. | H50: a validar
A51: churn_fijo | B51: Bajas mensuales de puestos fijos | C51: % | D51: 0.05 | E51: 0.04 | F51: 0.03 | G51: Supuesto (los fijos rotan menos). | H51: a validar
...

Sheet Inversion
A1: Inversión inicial (USD, mes 0)
A2: Se calcula desde Supuestos. El capital de trabajo no se suma acá: es la necesidad máxima de caja de cada escenario (ver Resumen).
A4: Rubro | B4: Cómo se calcula | D4: Conservador | E4: Base | F4: Favorable
A5: Obra de adecuación general | B5: m² intervenidos × USD/m² | D5: =Supuestos!$D$71*Supuestos!$D$72 -> 158496 | E5: =Supuestos!$E$71*Supuestos!$E$72 -> 118872 | F5: =Supuestos!$F$71*Supuestos!$F$72 -> 79248
A6: Techado del patio | B6: m² de patio × USD/m² | D6: =Supuestos!$D$73*Supuestos!$D$74 -> 3846 | E6: =Supuestos!$E$73*Supuestos!$E$74 -> 2844 | F6: =Supuestos!$F$73*Supuestos!$F$74 -> 1848
A7: Anulación / relleno de pileta | B7: suma fija | D7: =Supuestos!$D$75 -> 0 | E7: =Supuestos!$E$75 -> 0 | F7: =Supuestos!$F$75 -> 0
A8: Baño accesible | B8: suma fija | D8: =Supuestos!$D$76 -> 5769.2 | E8: =Supuestos!$E$76 -> 4487.2 | F8: =Supuestos!$F$76 -> 3205.1
A9: Instalación eléctrica y red de datos | B9: suma fija | D9: =Supuestos!$D$77 -> 7219.2 | E9: =Supuestos!$E$77 -> 5437.2 | F9: =Supuestos!$F$77 -> 3655.1
A10: Climatización | B10: equipos × USD por equipo instalado | D10: =Supuestos!$D$78*Supuestos!$D$79 -> 10342.4 | E10: =Supuestos!$E$78*Supuestos!$E$79 -> 7855.2 | F10: =Supuestos!$F$78*Supuestos!$F$79 -> 7254.4
A11: Mobiliario de puestos | B11: (puestos flex + fijos + oficinas) × USD por puesto | D11: =(Supuestos!$D$12+Supuestos!$D$13+Supuestos!$D$14*Supuestos!$D$15)*Supuestos!$D$80 -> 15384 | E11: =(Supuestos!$E$12+Supuestos!$E$13+Supuestos!$E$14*Supuestos!$E$15)*Supuestos!$E$80 -> 8308.8 | F11: =(Supuestos!$F$12+Supuestos!$F$13+Supuestos!$F$14*Supuestos!$F$15)*Supuestos!$F$80 -> 8378
A12: Mobiliario común (salas, living, lockers) | B12: suma fija | D12: =Supuestos!$D$81 -> 3982.6 | E12: =Supuestos!$E$81 -> 2876.5 | F12: =Supuestos!$F$81 -> 1434.3
A13: Cabinas para llamadas | B13: cabinas × USD | D13: =Supuestos!$D$82*Supuestos!$D$83 -> 0 | E13: =Supuestos!$E$82*Supuestos!$E$83 -> 0 | F13: =Supuestos!$F$82*Supuestos!$F$83 -> 0
A14: Café y cocina (equipamiento) | B14: suma fija | D14: =Supuestos!$D$84 -> 3509.3 | E14: =Supuestos!$E$84 -> 2145.7 | F14: =Supuestos!$F$84 -> 2120.7
A15: Conectividad, control de acceso y cámaras | B15: suma fija | D15: =Supuestos!$D$85 -> 2735.4 | E15: =Supuestos!$E$85 -> 1701.5 | F15: =Supuestos!$F$85 -> 1166.9
A16: Subtotal obra y equipamiento | D16: =SUM(D5:D15) -> 211284.1 | E16: =SUM(E5:E15) -> 154528.1 | F16: =SUM(F5:F15) -> 108310.5
A17: Honorarios profesionales (proyecto, dirección, planos) | B17: % sobre obra (filas de obra e instalaciones) | D17: =SUM(D5:D9)*Supuestos!$D$86 -> 24546.256 | E17: =SUM(E5:E9)*Supuestos!$E$86 -> 18429.656 | F17: =SUM(F5:F9)*Supuestos!$F$86 -> 12313.868
A18: Habilitación, planos de uso, incendio y trámites | B18: suma fija | D18: =Supuestos!$D$87 -> 1987.2 | E18: =Supuestos!$E$87 -> 1403.8 | F18: =Supuestos!$F$87 -> 726
A19: Marketing de apertura y preventa | B19: suma fija | D19: =Supuestos!$D$88 -> 2000 | E19: =Supuestos!$E$88 -> 2000 | F19: =Supuestos!$F$88 -> 2000
A20: Contingencias | B20: % sobre todo lo anterior | D20: =SUM(D16:D19)*Supuestos!$D$89 -> 35972.633 | E20: =SUM(E16:E19)*Supuestos!$E$89 -> 21163.387 | F20: =SUM(F16:F19)*Supuestos!$F$89 -> 12335.037
A21: INVERSIÓN INICIAL TOTAL (sin capital de trabajo) | D21: =SUM(D16:D20) -> 275790.19 | E21: =SUM(E16:E20) -> 197524.94 | F21: =SUM(F16:F20) -> 135685.4

Sheet Equilibrio
A1: Punto de equilibrio en régimen (mes tipo, con los supuestos de cada escenario)
A2: ¿Cuántos miembros flex hacen falta para cubrir los costos fijos, con los puestos fijos, oficinas y extras del mes 36? Comparado con el tope de puestos.
A4: Concepto | B4: Conservador | C4: Base | D4: Favorable | E4: Fórmula
A5: Precio neto promedio por miembro flex (USD/mes, sin IVA) | B5: =((Supuestos!$D$29*Supuestos!$D$25+Supuestos!$D$30*Supuestos!$D$26+Supuestos!$D$31*Supuestos!$D$27+Supuestos!$D$32*Supuestos!$D$28)*Supuestos!$D$37*(1-Supuestos!$D$38)/(1+Supuestos!$D$7*Supuestos!$D$8)/Supuestos!$D$6) -> 40.911952 | C5: =((Supuestos!$E$29*Supuestos!$E$25+Supuestos!$E$30*Supuestos!$E$26+Supuestos!$E$31*Supuestos!$E$27+Supuestos!$E$32*Supuestos!$E$28)*Supuestos!$E$37*(1-Supuestos!$E$38)/(1+Supuestos!$E$7*Supuestos!$E$8)/Supuestos!$E$6) -> 46.972982 | D5: =((Supuestos!$F$29*Supuestos!$F$25+Supuestos!$F$30*Supuestos!$F$26+Supuestos!$F$31*Supuestos!$F$27+Supuestos!$F$32*Supuestos!$F$28)*Supuestos!$F$37*(1-Supuestos!$F$38)/(1+Supuestos!$F$7*Supuestos!$F$8)/Supuestos!$F$6) -> 50.382311 | E5: mezcla de planes × precio × (1 − descuento) / IVA / TC
A6: Días promedio incluidos por miembro flex | B6: =(Supuestos!$D$29*Supuestos!$D$21+Supuestos!$D$30*Supuestos!$D$22+Supuestos!$D$31*Supuestos!$D$23+Supuestos!$D$32*Supuestos!$D$24) -> 12.05 | C6: =(Supuestos!$E$29*Supuestos!$E$21+Supuestos!$E$30*Supuestos!$E$22+Supuestos!$E$31*Supuestos!$E$23+Supuestos!$E$32*Supuestos!$E$24) -> 12.05 | D6: =(Supuestos!$F$29*Supuestos!$F$21+Supuestos!$F$30*Supuestos!$F$22+Supuestos!$F$31*Supuestos!$F$23+Supuestos!$F$32*Supuestos!$F$24) -> 12.05 | E6: mezcla × días de cada plan
A7: Costo variable por miembro flex (USD/mes) | B7: =(Supuestos!$D$29*Supuestos!$D$21+Supuestos!$D$30*Supuestos!$D$22+Supuestos!$D$31*Supuestos!$D$23+Supuestos!$D$32*Supuestos!$D$24)*Supuestos!$D$17*Supuestos!$D$53+((Supuestos!$D$29*Supuestos!$D$25+Supuestos!$D$30*Supuestos!$D$26+Supuestos!$D$31*Supuestos!$D$27+Supuestos!$D$32*Supuestos!$D$28)*Supuestos!$D$37*(1-Supuestos!$D$38)/(1+Supuestos!$D$7*Supuestos!$D$8)/Supuestos!$D$6)*((1+Supuestos!$D$7*Supuestos!$D$8)*(Supuestos!$D$54+Supuestos!$D$56)+Supuestos!$D$55) -> 18.249257 | C7: =(Supuestos!$E$29*Supuestos!$E$21+Supuestos!$E$30*Supuestos!$E$22+Supuestos!$E$31*Supuestos!$E$23+Supuestos!$E$32*Supuestos!$E$24)*Supuestos!$E$17*Supuestos!$E$53+((Supuestos!$E$29*Supuestos!$E$25+Supuestos!$E$30*Supuestos!$E$26+Supuestos!$E$31*Supuestos!$E$27+Supuestos!$E$32*Supuestos!$E$28)*Supuestos!$E$37*(1-Supuestos!$E$38)/(1+Supuestos!$E$7*Supuestos!$E$8)/Supuestos!$E$6)*((1+Supuestos!$E$7*Supuestos!$E$8)*(Supuestos!$E$54+Supuestos!$E$56)+Supuestos!$E$55) -> 11.860524 | D7: =(Supuestos!$F$29*Supuestos!$F$21+Supuestos!$F$30*Supuestos!$F$22+Supuestos!$F$31*Supuestos!$F$23+Supuestos!$F$32*Supuestos!$F$24)*Supuestos!$F$17*Supuestos!$F$53+((Supuestos!$F$29*Supuestos!$F$25+Supuestos!$F$30*Supuestos!$F$26+Supuestos!$F$31*Supuestos!$F$27+Supuestos!$F$32*Supuestos!$F$28)*Supuestos!$F$37*(1-Supuestos!$F$38)/(1+Supuestos!$F$7*Supuestos!$F$8)/Supuestos!$F$6)*((1+Supuestos!$F$7*Supuestos!$F$8)*(Supuestos!$F$54+Supuestos!$F$56)+Supuestos!$F$55) -> 6.3141711 | E7: consumo + comisiones + impuestos sobre ventas
A8: Contribución por miembro flex (USD/mes) | B8: =B5-B7 -> 22.662695 | C8: =C5-C7 -> 35.112457 | D8: =D5-D7 -> 44.06814 | E8: precio neto − costo variable
A9: Costos fijos del mes 36 | B9: =Modelo_Conservador!AM40 -> 5101.2999 | C9: =Modelo_Base!AM40 -> 3744.9473 | D9: =Modelo_Favorable!AM40 -> 3199.9114
A10: Contribución de fijos, oficinas y extras del mes 36 | B10: =Modelo_Conservador!AM28-Modelo_Conservador!AM7*B8 -> 464.25565 | C10: =Modelo_Base!AM28-Modelo_Base!AM7*C8 -> 1008.6114 | D10: =Modelo_Favorable!AM28-Modelo_Favorable!AM7*D8 -> 1813.6545 | E10: margen de contribución total − el de los miembros flex
A11: MIEMBROS FLEX NECESARIOS PARA EL EQUILIBRIO | B11: =MAX(0,(B9-B10)/B8) -> 204.61133 | C11: =MAX(0,(C9-C10)/C8) -> 77.930628 | D11: =MAX(0,(D9-D10)/D8) -> 31.457124 | E11: (fijos − otras contribuciones) / contribución por miembro
A12: Tope de miembros flex (puestos en el pico) | B12: =Modelo_Conservador!AM5 -> 45.561793 | C12: =Modelo_Base!AM5 -> 60.325567 | D12: =Modelo_Favorable!AM5 -> 78.074689
A13: Equilibrio como % del tope | B13: =B11/B12 -> 4.4908534 | C13: =C11/C12 -> 1.2918342 | D13: =D11/D12 -> 0.40291065 | E13: más de 80 %: el negocio depende de estar casi lleno

Sheet Sensibilidad
A1: Sensibilidad del resultado operativo mensual en régimen · escenario Base
A2: Miembros flex = % del tope de puestos. Precio = variación sobre los precios de Supuestos. Fijos, oficinas y extras como en el mes 36 del escenario Base. USD por mes, antes de Ganancias.
A4: Miembros flex (% del tope) ↓ / Precio → | B4: -0.2 | C4: -0.1 | D4: 0 | E4: 0.1 | F4: 0.2
A5: 0.4 | B5: =$A5*Equilibrio!C12*(Equilibrio!C5*(1+B$4)*(1-((1+Supuestos!$E$7*Supuestos!$E$8)*(Supuestos!$E$54+Supuestos!$E$56)+Supuestos!$E$55))-(Equilibrio!C7-Equilibrio!C5*((1+Supuestos!$E$7*Supuestos!$E$8)*(Supuestos!$E$54+Supuestos!$E$56)+Supuestos!$E$55)))+Equilibrio!C10*(1+B$4)-Equilibrio!C9 -> -2297.9246 | C5: =$A5*Equilibrio!C12*(Equilibrio!C5*(1+C$4)*(1-((1+Supuestos!$E$7*Supuestos!$E$8)*(Supuestos!$E$54+Supuestos!$E$56)+Supuestos!$E$55))-(Equilibrio!C7-Equilibrio!C5*((1+Supuestos!$E$7*Supuestos!$E$8)*(Supuestos!$E$54+Supuestos!$E$56)+Supuestos!$E$55)))+Equilibrio!C10*(1+C$4)-Equilibrio!C9 -> -2093.4945 | D5: =$A5*Equilibrio!C12*(Equilibrio!C5*(1+D$4)*(1-((1+Supuestos!$E$7*Supuestos!$E$8)*(Supuestos!$E$54+Supuestos!$E$56)+Supuestos!$E$55))-(Equilibrio!C7-Equilibrio!C5*((1+Supuestos!$E$7*Supuestos!$E$8)*(Supuestos!$E$54+Supuestos!$E$56)+Supuestos!$E$55)))+Equilibrio!C10*(1+D$4)-Equilibrio!C9 -> -1889.0643 | E5: =$A5*Equilibrio!C12*(Equilibrio!C5*(1+E$4)*(1-((1+Supuestos!$E$7*Supuestos!$E$8)*(Supuestos!$E$54+Supuestos!$E$56)+Supuestos!$E$55))-(Equilibrio!C7-Equilibrio!C5*((1+Supuestos!$E$7*Supuestos!$E$8)*(Supuestos!$E$54+Supuestos!$E$56)+Supuestos!$E$55)))+Equilibrio!C10*(1+E$4)-Equilibrio!C9 -> -1684.6342 | F5: =$A5*Equilibrio!C12*(Equilibrio!C5*(1+F$4)*(1-((1+Supuestos!$E$7*Supuestos!$E$8)*(Supuestos!$E$54+Supuestos!$E$56)+Supuestos!$E$55))-(Equilibrio!C7-Equilibrio!C5*((1+Supuestos!$E$7*Supuestos!$E$8)*(Supuestos!$E$54+Supuestos!$E$56)+Supuestos!$E$55)))+Equilibrio!C10*(1+F$4)-Equilibrio!C9 -> -1480.204
A6: 0.5 | B6: =$A6*Equilibrio!C12*(Equilibrio!C5*(1+B$4)*(1-((1+Supuestos!$E$7*Supuestos!$E$8)*(Supuestos!$E$54+Supuestos!$E$56)+Supuestos!$E$55))-(Equilibrio!C7-Equilibrio!C5*((1+Supuestos!$E$7*Supuestos!$E$8)*(Supuestos!$E$54+Supuestos!$E$56)+Supuestos!$E$55)))+Equilibrio!C10*(1+B$4)-Equilibrio!C9 -> -2137.8912 | C6: =$A6*Equilibrio!C12*(Equilibrio!C5*(1+C$4)*(1-((1+Supuestos!$E$7*Supuestos!$E$8)*(Supuestos!$E$54+Supuestos!$E$56)+Supuestos!$E$55))-(Equilibrio!C7-Equilibrio!C5*((1+Supuestos!$E$7*Supuestos!$E$8)*(Supuestos!$E$54+Supuestos!$E$56)+Supuestos!$E$55)))+Equilibrio!C10*(1+C$4)-Equilibrio!C9 -> -1907.5688 | D6: =$A6*Equilibrio!C12*(Equilibrio!C5*(1+D$4)*(1-((1+Supuestos!$E$7*Supuestos!$E$8)*(Supuestos!$E$54+Supuestos!$E$56)+Supuestos!$E$55))-(Equilibrio!C7-Equilibrio!C5*((1+Supuestos!$E$7*Supuestos!$E$8)*(Supuestos!$E$54+Supuestos!$E$56)+Supuestos!$E$55)))+Equilibrio!C10*(1+D$4)-Equilibrio!C9 -> -1677.2464 | E6: =$A6*Equilibrio!C12*(Equilibrio!C5*(1+E$4)*(1-((1+Supuestos!$E$7*Supuestos!$E$8)*(Supuestos!$E$54+Supuestos!$E$56)+Supuestos!$E$55))-(Equilibrio!C7-Equilibrio!C5*((1+Supuestos!$E$7*Supuestos!$E$8)*(Supuestos!$E$54+Supuestos!$E$56)+Supuestos!$E$55)))+Equilibrio!C10*(1+E$4)-Equilibrio!C9 -> -1446.924 | F6: =$A6*Equilibrio!C12*(Equilibrio!C5*(1+F$4)*(1-((1+Supuestos!$E$7*Supuestos!$E$8)*(Supuestos!$E$54+Supuestos!$E$56)+Supuestos!$E$55))-(Equilibrio!C7-Equilibrio!C5*((1+Supuestos!$E$7*Supuestos!$E$8)*(Supuestos!$E$54+Supuestos!$E$56)+Supuestos!$E$55)))+Equilibrio!C10*(1+F$4)-Equilibrio!C9 -> -1216.6016
A7: 0.6 | B7: =$A7*Equilibrio!C12*(Equilibrio!C5*(1+B$4)*(1-((1+Supuestos!$E$7*Supuestos!$E$8)*(Supuestos!$E$54+Supuestos!$E$56)+Supuestos!$E$55))-(Equilibrio!C7-Equilibrio!C5*((1+Supuestos!$E$7*Supuestos!$E$8)*(Supuestos!$E$54+Supuestos!$E$56)+Supuestos!$E$55)))+Equilibrio!C10*(1+B$4)-Equilibrio!C9 -> -1977.8578 | C7: =$A7*Equilibrio!C12*(Equilibrio!C5*(1+C$4)*(1-((1+Supuestos!$E$7*Supuestos!$E$8)*(Supuestos!$E$54+Supuestos!$E$56)+Supuestos!$E$55))-(Equilibrio!C7-Equilibrio!C5*((1+Supuestos!$E$7*Supuestos!$E$8)*(Supuestos!$E$54+Supuestos!$E$56)+Supuestos!$E$55)))+Equilibrio!C10*(1+C$4)-Equilibrio!C9 -> -1721.6432 | D7: =$A7*Equilibrio!C12*(Equilibrio!C5*(1+D$4)*(1-((1+Supuestos!$E$7*Supuestos!$E$8)*(Supuestos!$E$54+Supuestos!$E$56)+Supuestos!$E$55))-(Equilibrio!C7-Equilibrio!C5*((1+Supuestos!$E$7*Supuestos!$E$8)*(Supuestos!$E$54+Supuestos!$E$56)+Supuestos!$E$55)))+Equilibrio!C10*(1+D$4)-Equilibrio!C9 -> -1465.4285 | E7: =$A7*Equilibrio!C12*(Equilibrio!C5*(1+E$4)*(1-((1+Supuestos!$E$7*Supuestos!$E$8)*(Supuestos!$E$54+Supuestos!$E$56)+Supuestos!$E$55))-(Equilibrio!C7-Equilibrio!C5*((1+Supuestos!$E$7*Supuestos!$E$8)*(Supuestos!$E$54+Supuestos!$E$56)+Supuestos!$E$55)))+Equilibrio!C10*(1+E$4)-Equilibrio!C9 -> -1209.2139 | F7: =$A7*Equilibrio!C12*(Equilibrio!C5*(1+F$4)*(1-((1+Supuestos!$E$7*Supuestos!$E$8)*(Supuestos!$E$54+Supuestos!$E$56)+Supuestos!$E$55))-(Equilibrio!C7-Equilibrio!C5*((1+Supuestos!$E$7*Supuestos!$E$8)*(Supuestos!$E$54+Supuestos!$E$56)+Supuestos!$E$55)))+Equilibrio!C10*(1+F$4)-Equilibrio!C9 -> -952.99925
A8: 0.7 | B8: =$A8*Equilibrio!C12*(Equilibrio!C5*(1+B$4)*(1-((1+Supuestos!$E$7*Supuestos!$E$8)*(Supuestos!$E$54+Supuestos!$E$56)+Supuestos!$E$55))-(Equilibrio!C7-Equilibrio!C5*((1+Supuestos!$E$7*Supuestos!$E$8)*(Supuestos!$E$54+Supuestos!$E$56)+Supuestos!$E$55)))+Equilibrio!C10*(1+B$4)-Equilibrio!C9 -> -1817.8244 | C8: =$A8*Equilibrio!C12*(Equilibrio!C5*(1+C$4)*(1-((1+Supuestos!$E$7*Supuestos!$E$8)*(Supuestos!$E$54+Supuestos!$E$56)+Supuestos!$E$55))-(Equilibrio!C7-Equilibrio!C5*((1+Supuestos!$E$7*Supuestos!$E$8)*(Supuestos!$E$54+Supuestos!$E$56)+Supuestos!$E$55)))+Equilibrio!C10*(1+C$4)-Equilibrio!C9 -> -1535.7175 | D8: =$A8*Equilibrio!C12*(Equilibrio!C5*(1+D$4)*(1-((1+Supuestos!$E$7*Supuestos!$E$8)*(Supuestos!$E$54+Supuestos!$E$56)+Supuestos!$E$55))-(Equilibrio!C7-Equilibrio!C5*((1+Supuestos!$E$7*Supuestos!$E$8)*(Supuestos!$E$54+Supuestos!$E$56)+Supuestos!$E$55)))+Equilibrio!C10*(1+D$4)-Equilibrio!C9 -> -1253.6106 | E8: =$A8*Equilibrio!C12*(Equilibrio!C5*(1+E$4)*(1-((1+Supuestos!$E$7*Supuestos!$E$8)*(Supuestos!$E$54+Supuestos!$E$56)+Supuestos!$E$55))-(Equilibrio!C7-Equilibrio!C5*((1+Supuestos!$E$7*Supuestos!$E$8)*(Supuestos!$E$54+Supuestos!$E$56)+Supuestos!$E$55)))+Equilibrio!C10*(1+E$4)-Equilibrio!C9 -> -971.50375 | F8: =$A8*Equilibrio!C12*(Equilibrio!C5*(1+F$4)*(1-((1+Supuestos!$E$7*Supuestos!$E$8)*(Supuestos!$E$54+Supuestos!$E$56)+Supuestos!$E$55))-(Equilibrio!C7-Equilibrio!C5*((1+Supuestos!$E$7*Supuestos!$E$8)*(Supuestos!$E$54+Supuestos!$E$56)+Supuestos!$E$55)))+Equilibrio!C10*(1+F$4)-Equilibrio!C9 -> -689.39686
A9: 0.8 | B9: =$A9*Equilibrio!C12*(Equilibrio!C5*(1+B$4)*(1-((1+Supuestos!$E$7*Supuestos!$E$8)*(Supuestos!$E$54+Supuestos!$E$56)+Supuestos!$E$55))-(Equilibrio!C7-Equilibrio!C5*((1+Supuestos!$E$7*Supuestos!$E$8)*(Supuestos!$E$54+Supuestos!$E$56)+Supuestos!$E$55)))+Equilibrio!C10*(1+B$4)-Equilibrio!C9 -> -1657.7911 | C9: =$A9*Equilibrio!C12*(Equilibrio!C5*(1+C$4)*(1-((1+Supuestos!$E$7*Supuestos!$E$8)*(Supuestos!$E$54+Supuestos!$E$56)+Supuestos!$E$55))-(Equilibrio!C7-Equilibrio!C5*((1+Supuestos!$E$7*Supuestos!$E$8)*(Supuestos!$E$54+Supuestos!$E$56)+Supuestos!$E$55)))+Equilibrio!C10*(1+C$4)-Equilibrio!C9 -> -1349.7919 | D9: =$A9*Equilibrio!C12*(Equilibrio!C5*(1+D$4)*(1-((1+Supuestos!$E$7*Supuestos!$E$8)*(Supuestos!$E$54+Supuestos!$E$56)+Supuestos!$E$55))-(Equilibrio!C7-Equilibrio!C5*((1+Supuestos!$E$7*Supuestos!$E$8)*(Supuestos!$E$54+Supuestos!$E$56)+Supuestos!$E$55)))+Equilibrio!C10*(1+D$4)-Equilibrio!C9 -> -1041.7928 | E9: =$A9*Equilibrio!C12*(Equilibrio!C5*(1+E$4)*(1-((1+Supuestos!$E$7*Supuestos!$E$8)*(Supuestos!$E$54+Supuestos!$E$56)+Supuestos!$E$55))-(Equilibrio!C7-Equilibrio!C5*((1+Supuestos!$E$7*Supuestos!$E$8)*(Supuestos!$E$54+Supuestos!$E$56)+Supuestos!$E$55)))+Equilibrio!C10*(1+E$4)-Equilibrio!C9 -> -733.79362 | F9: =$A9*Equilibrio!C12*(Equilibrio!C5*(1+F$4)*(1-((1+Supuestos!$E$7*Supuestos!$E$8)*(Supuestos!$E$54+Supuestos!$E$56)+Supuestos!$E$55))-(Equilibrio!C7-Equilibrio!C5*((1+Supuestos!$E$7*Supuestos!$E$8)*(Supuestos!$E$54+Supuestos!$E$56)+Supuestos!$E$55)))+Equilibrio!C10*(1+F$4)-Equilibrio!C9 -> -425.79447
A10: 0.9 | B10: =$A10*Equilibrio!C12*(Equilibrio!C5*(1+B$4)*(1-((1+Supuestos!$E$7*Supuestos!$E$8)*(Supuestos!$E$54+Supuestos!$E$56)+Supuestos!$E$55))-(Equilibrio!C7-Equilibrio!C5*((1+Supuestos!$E$7*Supuestos!$E$8)*(Supuestos!$E$54+Supuestos!$E$56)+Supuestos!$E$55)))+Equilibrio!C10*(1+B$4)-Equilibrio!C9 -> -1497.7577 | C10: =$A10*Equilibrio!C12*(Equilibrio!C5*(1+C$4)*(1-((1+Supuestos!$E$7*Supuestos!$E$8)*(Supuestos!$E$54+Supuestos!$E$56)+Supuestos!$E$55))-(Equilibrio!C7-Equilibrio!C5*((1+Supuestos!$E$7*Supuestos!$E$8)*(Supuestos!$E$54+Supuestos!$E$56)+Supuestos!$E$55)))+Equilibrio!C10*(1+C$4)-Equilibrio!C9 -> -1163.8663 | D10: =$A10*Equilibrio!C12*(Equilibrio!C5*(1+D$4)*(1-((1+Supuestos!$E$7*Supuestos!$E$8)*(Supuestos!$E$54+Supuestos!$E$56)+Supuestos!$E$55))-(Equilibrio!C7-Equilibrio!C5*((1+Supuestos!$E$7*Supuestos!$E$8)*(Supuestos!$E$54+Supuestos!$E$56)+Supuestos!$E$55)))+Equilibrio!C10*(1+D$4)-Equilibrio!C9 -> -829.97487 | E10: =$A10*Equilibrio!C12*(Equilibrio!C5*(1+E$4)*(1-((1+Supuestos!$E$7*Supuestos!$E$8)*(Supuestos!$E$54+Supuestos!$E$56)+Supuestos!$E$55))-(Equilibrio!C7-Equilibrio!C5*((1+Supuestos!$E$7*Supuestos!$E$8)*(Supuestos!$E$54+Supuestos!$E$56)+Supuestos!$E$55)))+Equilibrio!C10*(1+E$4)-Equilibrio!C9 -> -496.08348 | F10: =$A10*Equilibrio!C12*(Equilibrio!C5*(1+F$4)*(1-((1+Supuestos!$E$7*Supuestos!$E$8)*(Supuestos!$E$54+Supuestos!$E$56)+Supuestos!$E$55))-(Equilibrio!C7-Equilibrio!C5*((1+Supuestos!$E$7*Supuestos!$E$8)*(Supuestos!$E$54+Supuestos!$E$56)+Supuestos!$E$55)))+Equilibrio!C10*(1+F$4)-Equilibrio!C9 -> -162.19208
A11: 1 | B11: =$A11*Equilibrio!C12*(Equilibrio!C5*(1+B$4)*(1-((1+Supuestos!$E$7*Supuestos!$E$8)*(Supuestos!$E$54+Supuestos!$E$56)+Supuestos!$E$55))-(Equilibrio!C7-Equilibrio!C5*((1+Supuestos!$E$7*Supuestos!$E$8)*(Supuestos!$E$54+Supuestos!$E$56)+Supuestos!$E$55)))+Equilibrio!C10*(1+B$4)-Equilibrio!C9 -> -1337.7243 | C11: =$A11*Equilibrio!C12*(Equilibrio!C5*(1+C$4)*(1-((1+Supuestos!$E$7*Supuestos!$E$8)*(Supuestos!$E$54+Supuestos!$E$56)+Supuestos!$E$55))-(Equilibrio!C7-Equilibrio!C5*((1+Supuestos!$E$7*Supuestos!$E$8)*(Supuestos!$E$54+Supuestos!$E$56)+Supuestos!$E$55)))+Equilibrio!C10*(1+C$4)-Equilibrio!C9 -> -977.94063 | D11: =$A11*Equilibrio!C12*(Equilibrio!C5*(1+D$4)*(1-((1+Supuestos!$E$7*Supuestos!$E$8)*(Supuestos!$E$54+Supuestos!$E$56)+Supuestos!$E$55))-(Equilibrio!C7-Equilibrio!C5*((1+Supuestos!$E$7*Supuestos!$E$8)*(Supuestos!$E$54+Supuestos!$E$56)+Supuestos!$E$55)))+Equilibrio!C10*(1+D$4)-Equilibrio!C9 -> -618.15699 | E11: =$A11*Equilibrio!C12*(Equilibrio!C5*(1+E$4)*(1-((1+Supuestos!$E$7*Supuestos!$E$8)*(Supuestos!$E$54+Supuestos!$E$56)+Supuestos!$E$55))-(Equilibrio!C7-Equilibrio!C5*((1+Supuestos!$E$7*Supuestos!$E$8)*(Supuestos!$E$54+Supuestos!$E$56)+Supuestos!$E$55)))+Equilibrio!C10*(1+E$4)-Equilibrio!C9 -> -258.37334 | F11: =$A11*Equilibrio!C12*(Equilibrio!C5*(1+F$4)*(1-((1+Supuestos!$E$7*Supuestos!$E$8)*(Supuestos!$E$54+Supuestos!$E$56)+Supuestos!$E$55))-(Equilibrio!C7-Equilibrio!C5*((1+Supuestos!$E$7*Supuestos!$E$8)*(Supuestos!$E$54+Supuestos!$E$56)+Supuestos!$E$55)))+Equilibrio!C10*(1+F$4)-Equilibrio!C9 -> 101.41031
A13: Lectura: en rojo, el mes da pérdida. La celda de 0 % de precio y la ocupación que alcanza el escenario Base es la del Resumen.
A15: Qué mueve más el resultado (mes en régimen, escenario Base, ±20 %)
A16: Variable | B16: −20 % | C16: +20 % | D16: Rango
A17: Precio de las membresías | B17: =Modelo_Base!AM7*Equilibrio!C8+Equilibrio!C10-Equilibrio!C9+Modelo_Base!AM7*Equilibrio!C5*(1-((1+Supuestos!$E$7*Supuestos!$E$8)*(Supuestos!$E$54+Supuestos!$E$56)+Supuestos!$E$55))*(-0.2) -> -1880.5993 | C17: =Modelo_Base!AM7*Equilibrio!C8+Equilibrio!C10-Equilibrio!C9+Modelo_Base!AM7*Equilibrio!C5*(1-((1+Supuestos!$E$7*Supuestos!$E$8)*(Supuestos!$E$54+Supuestos!$E$56)+Supuestos!$E$55))*(0.2) -> -1326.7912 | D17: =ABS(C17-B17) -> 553.80808
A18: Cantidad de miembros flex | B18: =Modelo_Base!AM7*0.8*Equilibrio!C8+Equilibrio!C10-Equilibrio!C9 -> -1830.2234 | C18: =MIN(Modelo_Base!AM7*1.2,Equilibrio!C12)*Equilibrio!C8+Equilibrio!C10-Equilibrio!C9 -> -1377.1671 | D18: =ABS(C18-B18) -> 453.05624
A19: Costos fijos | B19: =Modelo_Base!AM7*Equilibrio!C8+Equilibrio!C10-Equilibrio!C9*0.8 -> -854.70579 | C19: =Modelo_Base!AM7*Equilibrio!C8+Equilibrio!C10-Equilibrio!C9*1.2 -> -2352.6847 | D19: =ABS(C19-B19) -> 1497.9789
A20: Personal (sueldos y cargas) | B20: =Modelo_Base!AM7*Equilibrio!C8+Equilibrio!C10-Equilibrio!C9+Modelo_Base!AM30*0.2 -> -1272.2553 | C20: =Modelo_Base!AM7*Equilibrio!C8+Equilibrio!C10-Equilibrio!C9-Modelo_Base!AM30*0.2 -> -1935.1353 | D20: =ABS(C20-B20) -> 662.88
A22: Referencia: resultado del mes 36, escenario Base | B22: =Modelo_Base!AM42 -> -1603.6953

Sheet Modelo_Conservador
A1: Modelo mensual a 36 meses · escenario Conservador (USD constantes)
A2: Miembros = fin de mes. Ingresos sin IVA. Flujo de caja con la casa propia (sin alquiler pagado); abajo, el resultado económico restando el alquiler que se deja de cobrar.
B3: Mes | C3: 0 | D3: 1 | E3: 2 | F3: 3 | G3: 4 | H3: 5 | I3: 6 | J3: 7 | K3: 8 | L3: 9 | M3: 10 | N3: 11 | O3: 12 | P3: 13 | Q3: 14 | R3: 15 | S3: 16 | T3: 17 | U3: 18 | V3: 19 | W3: 20 | X3: 21 | Y3: 22 | Z3: 23 | AA3: 24 | AB3: 25 | AC3: 26 | AD3: 27 | AE3: 28 | AF3: 29 | AG3: 30 | AH3: 31 | AI3: 32 | AJ3: 33 | AK3: 34 | AL3: 35 | AM3: 36
B4: MIEMBROS Y OCUPACIÓN
B5: Tope de miembros flex que entran en los puestos (pico) | D5: =(Supuestos!$D$12*Supuestos!$D$9/((Supuestos!$D$29*Supuestos!$D$21+Supuestos!$D$30*Supuestos!$D$22+Supuestos!$D$31*Supuestos!$D$23+Supuestos!$D$32*Supuestos!$D$24)*Supuestos!$D$17*Supuestos!$D$18)) -> 45.561793 | E5: =(Supuestos!$D$12*Supuestos!$D$9/((Supuestos!$D$29*Supuestos!$D$21+Supuestos!$D$30*Supuestos!$D$22+Supuestos!$D$31*Supuestos!$D$23+Supuestos!$D$32*Supuestos!$D$24)*Supuestos!$D$17*Supuestos!$D$18)) -> 45.561793 | F5: =(Supuestos!$D$12*Supuestos!$D$9/((Supuestos!$D$29*Supuestos!$D$21+Supuestos!$D$30*Supuestos!$D$22+Supuestos!$D$31*Supuestos!$D$23+Supuestos!$D$32*Supuestos!$D$24)*Supuestos!$D$17*Supuestos!$D$18)) -> 45.561793 | G5: =(Supuestos!$D$12*Supuestos!$D$9/((Supuestos!$D$29*Supuestos!$D$21+Supuestos!$D$30*Supuestos!$D$22+Supuestos!$D$31*Supuestos!$D$23+Supuestos!$D$32*Supuestos!$D$24)*Supuestos!$D$17*Supuestos!$D$18)) -> 45.561793 | H5: =(Supuestos!$D$12*Supuestos!$D$9/((Supuestos!$D$29*Supuestos!$D$21+Supuestos!$D$30*Supuestos!$D$22+Supuestos!$D$31*Supuestos!$D$23+Supuestos!$D$32*Supuestos!$D$24)*Supuestos!$D$17*Supuestos!$D$18)) -> 45.561793 | I5: =(Supuestos!$D$12*Supuestos!$D$9/((Supuestos!$D$29*Supuestos!$D$21+Supuestos!$D$30*Supuestos!$D$22+Supuestos!$D$31*Supuestos!$D$23+Supuestos!$D$32*Supuestos!$D$24)*Supuestos!$D$17*Supuestos!$D$18)) -> 45.561793 | J5: =(Supuestos!$D$12*Supuestos!$D$9/((Supuestos!$D$29*Supuestos!$D$21+Supuestos!$D$30*Supuestos!$D$22+Supuestos!$D$31*Supuestos!$D$23+Supuestos!$D$32*Supuestos!$D$24)*Supuestos!$D$17*Supuestos!$D$18)) -> 45.561793 | K5: =(Supuestos!$D$12*Supuestos!$D$9/((Supuestos!$D$29*Supuestos!$D$21+Supuestos!$D$30*Supuestos!$D$22+Supuestos!$D$31*Supuestos!$D$23+Supuestos!$D$32*Supuestos!$D$24)*Supuestos!$D$17*Supuestos!$D$18)) -> 45.561793 | ... AM5: =(Supuestos!$D$12*Supuestos!$D$9/((Supuestos!$D$29*Supuestos!$D$21+Supuestos!$D$30*Supuestos!$D$22+Supuestos!$D$31*Supuestos!$D$23+Supuestos!$D$32*Supuestos!$D$24)*Supuestos!$D$17*Supuestos!$D$18)) -> 45.561793
B6: Altas de miembros flex en el mes | D6: =IF(D$3<=6,Supuestos!$D$46,IF(D$3<=12,Supuestos!$D$47,Supuestos!$D$48)) -> 2 | E6: =IF(E$3<=6,Supuestos!$D$46,IF(E$3<=12,Supuestos!$D$47,Supuestos!$D$48)) -> 2 | F6: =IF(F$3<=6,Supuestos!$D$46,IF(F$3<=12,Supuestos!$D$47,Supuestos!$D$48)) -> 2 | G6: =IF(G$3<=6,Supuestos!$D$46,IF(G$3<=12,Supuestos!$D$47,Supuestos!$D$48)) -> 2 | H6: =IF(H$3<=6,Supuestos!$D$46,IF(H$3<=12,Supuestos!$D$47,Supuestos!$D$48)) -> 2 | I6: =IF(I$3<=6,Supuestos!$D$46,IF(I$3<=12,Supuestos!$D$47,Supuestos!$D$48)) -> 2 | J6: =IF(J$3<=6,Supuestos!$D$46,IF(J$3<=12,Supuestos!$D$47,Supuestos!$D$48)) -> 2 | K6: =IF(K$3<=6,Supuestos!$D$46,IF(K$3<=12,Supuestos!$D$47,Supuestos!$D$48)) -> 2 | ... AM6: =IF(AM$3<=6,Supuestos!$D$46,IF(AM$3<=12,Supuestos!$D$47,Supuestos!$D$48)) -> 1
B7: Miembros flex (fin de mes) | D7: =MIN(D5,Supuestos!$D$45*(1-Supuestos!$D$49)+D6) -> 2 | E7: =MIN(E5,D7*(1-Supuestos!$D$49)+E6) -> 3.84 | F7: =MIN(F5,E7*(1-Supuestos!$D$49)+F6) -> 5.5328 | G7: =MIN(G5,F7*(1-Supuestos!$D$49)+G6) -> 7.090176 | H7: =MIN(H5,G7*(1-Supuestos!$D$49)+H6) -> 8.5229619 | I7: =MIN(I5,H7*(1-Supuestos!$D$49)+I6) -> 9.841125 | J7: =MIN(J5,I7*(1-Supuestos!$D$49)+J6) -> 11.053835 | K7: =MIN(K5,J7*(1-Supuestos!$D$49)+K6) -> 12.169528 | L7: =MIN(L5,K7*(1-Supuestos!$D$49)+L6) -> 13.195966 | ... AM7: =MIN(AM5,AL7*(1-Supuestos!$D$49)+AM6) -> 12.947217
B8: Bajas estimadas de flex en el mes | D8: =Supuestos!$D$45*Supuestos!$D$49 -> 0 | E8: =D7*Supuestos!$D$49 -> 0.16 | F8: =E7*Supuestos!$D$49 -> 0.3072 | G8: =F7*Supuestos!$D$49 -> 0.442624 | H8: =G7*Supuestos!$D$49 -> 0.56721408 | I8: =H7*Supuestos!$D$49 -> 0.68183695 | J8: =I7*Supuestos!$D$49 -> 0.78729 | K8: =J7*Supuestos!$D$49 -> 0.8843068 | L8: =K7*Supuestos!$D$49 -> 0.97356225 | ... AM8: =AL7*Supuestos!$D$49 -> 1.0388884
B9: Puestos fijos ocupados | D9: =MIN(Supuestos!$D$13,Supuestos!$D$50) -> 0.5 | E9: =MIN(Supuestos!$D$13,D9*(1-Supuestos!$D$51)+Supuestos!$D$50) -> 0.975 | F9: =MIN(Supuestos!$D$13,E9*(1-Supuestos!$D$51)+Supuestos!$D$50) -> 1.42625 | G9: =MIN(Supuestos!$D$13,F9*(1-Supuestos!$D$51)+Supuestos!$D$50) -> 1.8549375 | H9: =MIN(Supuestos!$D$13,G9*(1-Supuestos!$D$51)+Supuestos!$D$50) -> 2.2621906 | I9: =MIN(Supuestos!$D$13,H9*(1-Supuestos!$D$51)+Supuestos!$D$50) -> 2.6490811 | J9: =MIN(Supuestos!$D$13,I9*(1-Supuestos!$D$51)+Supuestos!$D$50) -> 3.016627 | K9: =MIN(Supuestos!$D$13,J9*(1-Supuestos!$D$51)+Supuestos!$D$50) -> 3.3657957 | L9: =MIN(Supuestos!$D$13,K9*(1-Supuestos!$D$51)+Supuestos!$D$50) -> 3.6975059 | ... AM9: =MIN(Supuestos!$D$13,AL9*(1-Supuestos!$D$51)+Supuestos!$D$50) -> 4
B10: Oficinas privadas ocupadas | D10: =Supuestos!$D$14*MIN(1,D$3/Supuestos!$D$43) -> 0.2 | E10: =Supuestos!$D$14*MIN(1,E$3/Supuestos!$D$43) -> 0.4 | F10: =Supuestos!$D$14*MIN(1,F$3/Supuestos!$D$43) -> 0.6 | G10: =Supuestos!$D$14*MIN(1,G$3/Supuestos!$D$43) -> 0.8 | H10: =Supuestos!$D$14*MIN(1,H$3/Supuestos!$D$43) -> 1 | I10: =Supuestos!$D$14*MIN(1,I$3/Supuestos!$D$43) -> 1.2 | J10: =Supuestos!$D$14*MIN(1,J$3/Supuestos!$D$43) -> 1.4 | K10: =Supuestos!$D$14*MIN(1,K$3/Supuestos!$D$43) -> 1.6 | ... AM10: =Supuestos!$D$14*MIN(1,AM$3/Supuestos!$D$43) -> 2
B11: Puestos-día usados por miembros flex | D11: =D7*(Supuestos!$D$29*Supuestos!$D$21+Supuestos!$D$30*Supuestos!$D$22+Supuestos!$D$31*Supuestos!$D$23+Supuestos!$D$32*Supuestos!$D$24)*Supuestos!$D$17 -> 20.485 | E11: =E7*(Supuestos!$D$29*Supuestos!$D$21+Supuestos!$D$30*Supuestos!$D$22+Supuestos!$D$31*Supuestos!$D$23+Supuestos!$D$32*Supuestos!$D$24)*Supuestos!$D$17 -> 39.3312 | F11: =F7*(Supuestos!$D$29*Supuestos!$D$21+Supuestos!$D$30*Supuestos!$D$22+Supuestos!$D$31*Supuestos!$D$23+Supuestos!$D$32*Supuestos!$D$24)*Supuestos!$D$17 -> 56.669704 | G11: =G7*(Supuestos!$D$29*Supuestos!$D$21+Supuestos!$D$30*Supuestos!$D$22+Supuestos!$D$31*Supuestos!$D$23+Supuestos!$D$32*Supuestos!$D$24)*Supuestos!$D$17 -> 72.621128 | H11: =H7*(Supuestos!$D$29*Supuestos!$D$21+Supuestos!$D$30*Supuestos!$D$22+Supuestos!$D$31*Supuestos!$D$23+Supuestos!$D$32*Supuestos!$D$24)*Supuestos!$D$17 -> 87.296437 | I11: =I7*(Supuestos!$D$29*Supuestos!$D$21+Supuestos!$D$30*Supuestos!$D$22+Supuestos!$D$31*Supuestos!$D$23+Supuestos!$D$32*Supuestos!$D$24)*Supuestos!$D$17 -> 100.79772 | J11: =J7*(Supuestos!$D$29*Supuestos!$D$21+Supuestos!$D$30*Supuestos!$D$22+Supuestos!$D$31*Supuestos!$D$23+Supuestos!$D$32*Supuestos!$D$24)*Supuestos!$D$17 -> 113.2189 | K11: =K7*(Supuestos!$D$29*Supuestos!$D$21+Supuestos!$D$30*Supuestos!$D$22+Supuestos!$D$31*Supuestos!$D$23+Supuestos!$D$32*Supuestos!$D$24)*Supuestos!$D$17 -> 124.64639 | ... AM11: =AM7*(Supuestos!$D$29*Supuestos!$D$21+Supuestos!$D$30*Supuestos!$D$22+Supuestos!$D$31*Supuestos!$D$23+Supuestos!$D$32*Supuestos!$D$24)*Supuestos!$D$17 -> 132.61187
B12: Ocupación promedio de puestos flex (días hábiles) | D12: =D11/(Supuestos!$D$12*Supuestos!$D$9) -> 0.032515873 | E12: =E11/(Supuestos!$D$12*Supuestos!$D$9) -> 0.062430476 | F12: =F11/(Supuestos!$D$12*Supuestos!$D$9) -> 0.089951911 | G12: =G11/(Supuestos!$D$12*Supuestos!$D$9) -> 0.11527163 | H12: =H11/(Supuestos!$D$12*Supuestos!$D$9) -> 0.13856577 | I12: =I11/(Supuestos!$D$12*Supuestos!$D$9) -> 0.15999638 | J12: =J11/(Supuestos!$D$12*Supuestos!$D$9) -> 0.17971255 | K12: =K11/(Supuestos!$D$12*Supuestos!$D$9) -> 0.19785142 | ... AM12: =AM11/(Supuestos!$D$12*Supuestos!$D$9) -> 0.21049503
B13: Puestos flex simultáneos en el pico (estimado) | D13: =D11/Supuestos!$D$9*Supuestos!$D$18 -> 1.3168929 | E13: =E11/Supuestos!$D$9*Supuestos!$D$18 -> 2.5284343 | F13: =F11/Supuestos!$D$9*Supuestos!$D$18 -> 3.6430524 | G13: =G11/Supuestos!$D$9*Supuestos!$D$18 -> 4.6685011 | H13: =H11/Supuestos!$D$9*Supuestos!$D$18 -> 5.6119138 | I13: =I11/Supuestos!$D$9*Supuestos!$D$18 -> 6.4798536 | J13: =J11/Supuestos!$D$9*Supuestos!$D$18 -> 7.2783582 | K13: =K11/Supuestos!$D$9*Supuestos!$D$18 -> 8.0129824 | ... AM13: =AM11/Supuestos!$D$9*Supuestos!$D$18 -> 8.5250486
B14: INGRESOS (USD sin IVA)
B15: Membresías flex (días por mes / ilimitado) | D15: =D7*((Supuestos!$D$29*Supuestos!$D$25+Supuestos!$D$30*Supuestos!$D$26+Supuestos!$D$31*Supuestos!$D$27+Supuestos!$D$32*Supuestos!$D$28)*Supuestos!$D$37)*(1-Supuestos!$D$38)/(1+Supuestos!$D$7*Supuestos!$D$8)/Supuestos!$D$6 -> 81.823903 | E15: =E7*((Supuestos!$D$29*Supuestos!$D$25+Supuestos!$D$30*Supuestos!$D$26+Supuestos!$D$31*Supuestos!$D$27+Supuestos!$D$32*Supuestos!$D$28)*Supuestos!$D$37)*(1-Supuestos!$D$38)/(1+Supuestos!$D$7*Supuestos!$D$8)/Supuestos!$D$6 -> 157.10189 | F15: =F7*((Supuestos!$D$29*Supuestos!$D$25+Supuestos!$D$30*Supuestos!$D$26+Supuestos!$D$31*Supuestos!$D$27+Supuestos!$D$32*Supuestos!$D$28)*Supuestos!$D$37)*(1-Supuestos!$D$38)/(1+Supuestos!$D$7*Supuestos!$D$8)/Supuestos!$D$6 -> 226.35765 | G15: =G7*((Supuestos!$D$29*Supuestos!$D$25+Supuestos!$D$30*Supuestos!$D$26+Supuestos!$D$31*Supuestos!$D$27+Supuestos!$D$32*Supuestos!$D$28)*Supuestos!$D$37)*(1-Supuestos!$D$38)/(1+Supuestos!$D$7*Supuestos!$D$8)/Supuestos!$D$6 -> 290.07294 | H15: =H7*((Supuestos!$D$29*Supuestos!$D$25+Supuestos!$D$30*Supuestos!$D$26+Supuestos!$D$31*Supuestos!$D$27+Supuestos!$D$32*Supuestos!$D$28)*Supuestos!$D$37)*(1-Supuestos!$D$38)/(1+Supuestos!$D$7*Supuestos!$D$8)/Supuestos!$D$6 -> 348.69101 | I15: =I7*((Supuestos!$D$29*Supuestos!$D$25+Supuestos!$D$30*Supuestos!$D$26+Supuestos!$D$31*Supuestos!$D$27+Supuestos!$D$32*Supuestos!$D$28)*Supuestos!$D$37)*(1-Supuestos!$D$38)/(1+Supuestos!$D$7*Supuestos!$D$8)/Supuestos!$D$6 -> 402.61963 | J15: =J7*((Supuestos!$D$29*Supuestos!$D$25+Supuestos!$D$30*Supuestos!$D$26+Supuestos!$D$31*Supuestos!$D$27+Supuestos!$D$32*Supuestos!$D$28)*Supuestos!$D$37)*(1-Supuestos!$D$38)/(1+Supuestos!$D$7*Supuestos!$D$8)/Supuestos!$D$6 -> 452.23396 | K15: =K7*((Supuestos!$D$29*Supuestos!$D$25+Supuestos!$D$30*Supuestos!$D$26+Supuestos!$D$31*Supuestos!$D$27+Supuestos!$D$32*Supuestos!$D$28)*Supuestos!$D$37)*(1-Supuestos!$D$38)/(1+Supuestos!$D$7*Supuestos!$D$8)/Supuestos!$D$6 -> 497.87915 | ... AM15: =AM7*((Supuestos!$D$29*Supuestos!$D$25+Supuestos!$D$30*Supuestos!$D$26+Supuestos!$D$31*Supuestos!$D$27+Supuestos!$D$32*Supuestos!$D$28)*Supuestos!$D$37)*(1-Supuestos!$D$38)/(1+Supuestos!$D$7*Supuestos!$D$8)/Supuestos!$D$6 -> 529.6959
B16: Puestos fijos | D16: =D9*Supuestos!$D$33*Supuestos!$D$37*(1-Supuestos!$D$38)/(1+Supuestos!$D$7*Supuestos!$D$8)/Supuestos!$D$6 -> 25.317864 | E16: =E9*Supuestos!$D$33*Supuestos!$D$37*(1-Supuestos!$D$38)/(1+Supuestos!$D$7*Supuestos!$D$8)/Supuestos!$D$6 -> 49.369835 | F16: =F9*Supuestos!$D$33*Supuestos!$D$37*(1-Supuestos!$D$38)/(1+Supuestos!$D$7*Supuestos!$D$8)/Supuestos!$D$6 -> 72.219207 | G16: =G9*Supuestos!$D$33*Supuestos!$D$37*(1-Supuestos!$D$38)/(1+Supuestos!$D$7*Supuestos!$D$8)/Supuestos!$D$6 -> 93.926111 | H16: =H9*Supuestos!$D$33*Supuestos!$D$37*(1-Supuestos!$D$38)/(1+Supuestos!$D$7*Supuestos!$D$8)/Supuestos!$D$6 -> 114.54767 | I16: =I9*Supuestos!$D$33*Supuestos!$D$37*(1-Supuestos!$D$38)/(1+Supuestos!$D$7*Supuestos!$D$8)/Supuestos!$D$6 -> 134.13815 | J16: =J9*Supuestos!$D$33*Supuestos!$D$37*(1-Supuestos!$D$38)/(1+Supuestos!$D$7*Supuestos!$D$8)/Supuestos!$D$6 -> 152.74911 | K16: =K9*Supuestos!$D$33*Supuestos!$D$37*(1-Supuestos!$D$38)/(1+Supuestos!$D$7*Supuestos!$D$8)/Supuestos!$D$6 -> 170.42951 | ... AM16: =AM9*Supuestos!$D$33*Supuestos!$D$37*(1-Supuestos!$D$38)/(1+Supuestos!$D$7*Supuestos!$D$8)/Supuestos!$D$6 -> 202.54291
B17: Oficinas privadas (complemento) | D17: =D10*Supuestos!$D$34*Supuestos!$D$37*(1-Supuestos!$D$38)/(1+Supuestos!$D$7*Supuestos!$D$8)/Supuestos!$D$6 -> 41.195168 | E17: =E10*Supuestos!$D$34*Supuestos!$D$37*(1-Supuestos!$D$38)/(1+Supuestos!$D$7*Supuestos!$D$8)/Supuestos!$D$6 -> 82.390337 | F17: =F10*Supuestos!$D$34*Supuestos!$D$37*(1-Supuestos!$D$38)/(1+Supuestos!$D$7*Supuestos!$D$8)/Supuestos!$D$6 -> 123.58551 | G17: =G10*Supuestos!$D$34*Supuestos!$D$37*(1-Supuestos!$D$38)/(1+Supuestos!$D$7*Supuestos!$D$8)/Supuestos!$D$6 -> 164.78067 | H17: =H10*Supuestos!$D$34*Supuestos!$D$37*(1-Supuestos!$D$38)/(1+Supuestos!$D$7*Supuestos!$D$8)/Supuestos!$D$6 -> 205.97584 | I17: =I10*Supuestos!$D$34*Supuestos!$D$37*(1-Supuestos!$D$38)/(1+Supuestos!$D$7*Supuestos!$D$8)/Supuestos!$D$6 -> 247.17101 | J17: =J10*Supuestos!$D$34*Supuestos!$D$37*(1-Supuestos!$D$38)/(1+Supuestos!$D$7*Supuestos!$D$8)/Supuestos!$D$6 -> 288.36618 | K17: =K10*Supuestos!$D$34*Supuestos!$D$37*(1-Supuestos!$D$38)/(1+Supuestos!$D$7*Supuestos!$D$8)/Supuestos!$D$6 -> 329.56135 | ... AM17: =AM10*Supuestos!$D$34*Supuestos!$D$37*(1-Supuestos!$D$38)/(1+Supuestos!$D$7*Supuestos!$D$8)/Supuestos!$D$6 -> 411.95168
B18: Pases diarios | D18: =Supuestos!$D$39*MIN(1,D$3/Supuestos!$D$42)*Supuestos!$D$35*Supuestos!$D$37/(1+Supuestos!$D$7*Supuestos!$D$8)/Supuestos!$D$6 -> 10.88684 | E18: =Supuestos!$D$39*MIN(1,E$3/Supuestos!$D$42)*Supuestos!$D$35*Supuestos!$D$37/(1+Supuestos!$D$7*Supuestos!$D$8)/Supuestos!$D$6 -> 21.773681 | F18: =Supuestos!$D$39*MIN(1,F$3/Supuestos!$D$42)*Supuestos!$D$35*Supuestos!$D$37/(1+Supuestos!$D$7*Supuestos!$D$8)/Supuestos!$D$6 -> 32.660521 | G18: =Supuestos!$D$39*MIN(1,G$3/Supuestos!$D$42)*Supuestos!$D$35*Supuestos!$D$37/(1+Supuestos!$D$7*Supuestos!$D$8)/Supuestos!$D$6 -> 43.547362 | H18: =Supuestos!$D$39*MIN(1,H$3/Supuestos!$D$42)*Supuestos!$D$35*Supuestos!$D$37/(1+Supuestos!$D$7*Supuestos!$D$8)/Supuestos!$D$6 -> 54.434202 | I18: =Supuestos!$D$39*MIN(1,I$3/Supuestos!$D$42)*Supuestos!$D$35*Supuestos!$D$37/(1+Supuestos!$D$7*Supuestos!$D$8)/Supuestos!$D$6 -> 65.321043 | J18: =Supuestos!$D$39*MIN(1,J$3/Supuestos!$D$42)*Supuestos!$D$35*Supuestos!$D$37/(1+Supuestos!$D$7*Supuestos!$D$8)/Supuestos!$D$6 -> 76.207883 | K18: =Supuestos!$D$39*MIN(1,K$3/Supuestos!$D$42)*Supuestos!$D$35*Supuestos!$D$37/(1+Supuestos!$D$7*Supuestos!$D$8)/Supuestos!$D$6 -> 87.094723 | ... AM18: =Supuestos!$D$39*MIN(1,AM$3/Supuestos!$D$42)*Supuestos!$D$35*Supuestos!$D$37/(1+Supuestos!$D$7*Supuestos!$D$8)/Supuestos!$D$6 -> 130.64209
B19: Salas por hora a externos | D19: =Supuestos!$D$40*MIN(1,D$3/Supuestos!$D$42)*Supuestos!$D$36*Supuestos!$D$37/(1+Supuestos!$D$7*Supuestos!$D$8)/Supuestos!$D$6 -> 5.1652893 | E19: =Supuestos!$D$40*MIN(1,E$3/Supuestos!$D$42)*Supuestos!$D$36*Supuestos!$D$37/(1+Supuestos!$D$7*Supuestos!$D$8)/Supuestos!$D$6 -> 10.330579 | F19: =Supuestos!$D$40*MIN(1,F$3/Supuestos!$D$42)*Supuestos!$D$36*Supuestos!$D$37/(1+Supuestos!$D$7*Supuestos!$D$8)/Supuestos!$D$6 -> 15.495868 | G19: =Supuestos!$D$40*MIN(1,G$3/Supuestos!$D$42)*Supuestos!$D$36*Supuestos!$D$37/(1+Supuestos!$D$7*Supuestos!$D$8)/Supuestos!$D$6 -> 20.661157 | H19: =Supuestos!$D$40*MIN(1,H$3/Supuestos!$D$42)*Supuestos!$D$36*Supuestos!$D$37/(1+Supuestos!$D$7*Supuestos!$D$8)/Supuestos!$D$6 -> 25.826446 | I19: =Supuestos!$D$40*MIN(1,I$3/Supuestos!$D$42)*Supuestos!$D$36*Supuestos!$D$37/(1+Supuestos!$D$7*Supuestos!$D$8)/Supuestos!$D$6 -> 30.991736 | J19: =Supuestos!$D$40*MIN(1,J$3/Supuestos!$D$42)*Supuestos!$D$36*Supuestos!$D$37/(1+Supuestos!$D$7*Supuestos!$D$8)/Supuestos!$D$6 -> 36.157025 | K19: =Supuestos!$D$40*MIN(1,K$3/Supuestos!$D$42)*Supuestos!$D$36*Supuestos!$D$37/(1+Supuestos!$D$7*Supuestos!$D$8)/Supuestos!$D$6 -> 41.322314 | ... AM19: =Supuestos!$D$40*MIN(1,AM$3/Supuestos!$D$42)*Supuestos!$D$36*Supuestos!$D$37/(1+Supuestos!$D$7*Supuestos!$D$8)/Supuestos!$D$6 -> 61.983471
B20: Otros (domicilio comercial, eventos) | D20: =Supuestos!$D$41*MIN(1,D$3/Supuestos!$D$42) -> 0 | E20: =Supuestos!$D$41*MIN(1,E$3/Supuestos!$D$42) -> 0 | F20: =Supuestos!$D$41*MIN(1,F$3/Supuestos!$D$42) -> 0 | G20: =Supuestos!$D$41*MIN(1,G$3/Supuestos!$D$42) -> 0 | H20: =Supuestos!$D$41*MIN(1,H$3/Supuestos!$D$42) -> 0 | I20: =Supuestos!$D$41*MIN(1,I$3/Supuestos!$D$42) -> 0 | J20: =Supuestos!$D$41*MIN(1,J$3/Supuestos!$D$42) -> 0 | K20: =Supuestos!$D$41*MIN(1,K$3/Supuestos!$D$42) -> 0 | ... AM20: =Supuestos!$D$41*MIN(1,AM$3/Supuestos!$D$42) -> 0
B21: INGRESOS TOTALES | D21: =SUM(D15:D20) -> 164.38907 | E21: =SUM(E15:E20) -> 320.96633 | F21: =SUM(F15:F20) -> 470.31875 | G21: =SUM(G15:G20) -> 612.98824 | H21: =SUM(H15:H20) -> 749.47517 | I21: =SUM(I15:I20) -> 880.24157 | J21: =SUM(J15:J20) -> 1005.7142 | K21: =SUM(K15:K20) -> 1126.287 | ... AM21: =SUM(AM15:AM20) -> 1336.8161
B22: COSTOS VARIABLES
B23: Café, té, agua y consumibles | D23: =(D11+D9*Supuestos!$D$9*Supuestos!$D$19+(D10*Supuestos!$D$15*Supuestos!$D$9*Supuestos!$D$19)+Supuestos!$D$39*MIN(1,D$3/Supuestos!$D$42))*Supuestos!$D$53 -> 49.570633 | E23: =(E11+E9*Supuestos!$D$9*Supuestos!$D$19+(E10*Supuestos!$D$15*Supuestos!$D$9*Supuestos!$D$19)+Supuestos!$D$39*MIN(1,E$3/Supuestos!$D$42))*Supuestos!$D$53 -> 96.629531 | F23: =(F11+F9*Supuestos!$D$9*Supuestos!$D$19+(F10*Supuestos!$D$15*Supuestos!$D$9*Supuestos!$D$19)+Supuestos!$D$39*MIN(1,F$3/Supuestos!$D$42))*Supuestos!$D$53 -> 141.36226 | G23: =(G11+G9*Supuestos!$D$9*Supuestos!$D$19+(G10*Supuestos!$D$15*Supuestos!$D$9*Supuestos!$D$19)+Supuestos!$D$39*MIN(1,G$3/Supuestos!$D$42))*Supuestos!$D$53 -> 183.94031 | H23: =(H11+H9*Supuestos!$D$9*Supuestos!$D$19+(H10*Supuestos!$D$15*Supuestos!$D$9*Supuestos!$D$19)+Supuestos!$D$39*MIN(1,H$3/Supuestos!$D$42))*Supuestos!$D$53 -> 224.52218 | I23: =(I11+I9*Supuestos!$D$9*Supuestos!$D$19+(I10*Supuestos!$D$15*Supuestos!$D$9*Supuestos!$D$19)+Supuestos!$D$39*MIN(1,I$3/Supuestos!$D$42))*Supuestos!$D$53 -> 263.25439 | J23: =(J11+J9*Supuestos!$D$9*Supuestos!$D$19+(J10*Supuestos!$D$15*Supuestos!$D$9*Supuestos!$D$19)+Supuestos!$D$39*MIN(1,J$3/Supuestos!$D$42))*Supuestos!$D$53 -> 300.27238 | K23: =(K11+K9*Supuestos!$D$9*Supuestos!$D$19+(K10*Supuestos!$D$15*Supuestos!$D$9*Supuestos!$D$19)+Supuestos!$D$39*MIN(1,K$3/Supuestos!$D$42))*Supuestos!$D$53 -> 335.70141 | ... AM23: =(AM11+AM9*Supuestos!$D$9*Supuestos!$D$19+(AM10*Supuestos!$D$15*Supuestos!$D$9*Supuestos!$D$19)+Supuestos!$D$39*MIN(1,AM$3/Supuestos!$D$42))*Supuestos!$D$53 -> 391.14648
B24: Comisiones de cobro | D24: =D21*(1+Supuestos!$D$7*Supuestos!$D$8)*Supuestos!$D$54 -> 12.511487 | E24: =E21*(1+Supuestos!$D$7*Supuestos!$D$8)*Supuestos!$D$54 -> 24.428426 | F24: =F21*(1+Supuestos!$D$7*Supuestos!$D$8)*Supuestos!$D$54 -> 35.79549 | G24: =G21*(1+Supuestos!$D$7*Supuestos!$D$8)*Supuestos!$D$54 -> 46.653922 | H24: =H21*(1+Supuestos!$D$7*Supuestos!$D$8)*Supuestos!$D$54 -> 57.041805 | I24: =I21*(1+Supuestos!$D$7*Supuestos!$D$8)*Supuestos!$D$54 -> 66.994305 | J24: =J21*(1+Supuestos!$D$7*Supuestos!$D$8)*Supuestos!$D$54 -> 76.543899 | K24: =K21*(1+Supuestos!$D$7*Supuestos!$D$8)*Supuestos!$D$54 -> 85.720581 | ... AM24: =AM21*(1+Supuestos!$D$7*Supuestos!$D$8)*Supuestos!$D$54 -> 101.74373
B25: Ingresos Brutos | D25: =D21*Supuestos!$D$55 -> 8.2194533 | E25: =E21*Supuestos!$D$55 -> 16.048316 | F25: =F21*Supuestos!$D$55 -> 23.515937 | G25: =G21*Supuestos!$D$55 -> 30.649412 | H25: =H21*Supuestos!$D$55 -> 37.473758 | I25: =I21*Supuestos!$D$55 -> 44.012078 | J25: =J21*Supuestos!$D$55 -> 50.285708 | K25: =K21*Supuestos!$D$55 -> 56.314352 | ... AM25: =AM21*Supuestos!$D$55 -> 66.840803
B26: Impuesto a los débitos y créditos (aprox.) | D26: =D21*(1+Supuestos!$D$7*Supuestos!$D$8)*Supuestos!$D$56 -> 2.3869292 | E26: =E21*(1+Supuestos!$D$7*Supuestos!$D$8)*Supuestos!$D$56 -> 4.660431 | F26: =F21*(1+Supuestos!$D$7*Supuestos!$D$8)*Supuestos!$D$56 -> 6.8290282 | G26: =G21*(1+Supuestos!$D$7*Supuestos!$D$8)*Supuestos!$D$56 -> 8.9005893 | H26: =H21*(1+Supuestos!$D$7*Supuestos!$D$8)*Supuestos!$D$56 -> 10.882379 | I26: =I21*(1+Supuestos!$D$7*Supuestos!$D$8)*Supuestos!$D$56 -> 12.781108 | J26: =J21*(1+Supuestos!$D$7*Supuestos!$D$8)*Supuestos!$D$56 -> 14.60297 | K26: =K21*(1+Supuestos!$D$7*Supuestos!$D$8)*Supuestos!$D$56 -> 16.353688 | ... AM26: =AM21*(1+Supuestos!$D$7*Supuestos!$D$8)*Supuestos!$D$56 -> 19.410569
B27: Total costos variables | D27: =SUM(D23:D26) -> 72.688503 | E27: =SUM(E23:E26) -> 141.7667 | F27: =SUM(F23:F26) -> 207.50271 | G27: =SUM(G23:G26) -> 270.14423 | H27: =SUM(H23:H26) -> 329.92012 | I27: =SUM(I23:I26) -> 387.04188 | J27: =SUM(J23:J26) -> 441.70496 | K27: =SUM(K23:K26) -> 494.09004 | ... AM27: =SUM(AM23:AM26) -> 579.14158
B28: MARGEN DE CONTRIBUCIÓN | D28: =D21-D27 -> 91.700562 | E28: =E21-E27 -> 179.19962 | F28: =F21-F27 -> 262.81603 | G28: =G21-G27 -> 342.84401 | H28: =H21-H27 -> 419.55504 | I28: =I21-I27 -> 493.19969 | J28: =J21-J27 -> 564.00919 | K28: =K21-K27 -> 632.19701 | ... AM28: =AM21-AM27 -> 757.67447
B29: COSTOS FIJOS MENSUALES
B30: Personal (recepción / comunidad), con cargas | D30: =Supuestos!$D$58*Supuestos!$D$59 -> 1739.4 | E30: =Supuestos!$D$58*Supuestos!$D$59 -> 1739.4 | F30: =Supuestos!$D$58*Supuestos!$D$59 -> 1739.4 | G30: =Supuestos!$D$58*Supuestos!$D$59 -> 1739.4 | H30: =Supuestos!$D$58*Supuestos!$D$59 -> 1739.4 | I30: =Supuestos!$D$58*Supuestos!$D$59 -> 1739.4 | J30: =Supuestos!$D$58*Supuestos!$D$59 -> 1739.4 | K30: =Supuestos!$D$58*Supuestos!$D$59 -> 1739.4 | ... AM30: =Supuestos!$D$58*Supuestos!$D$59 -> 1739.4
