Workbook

Sheet Cómo usar
B1: CRM Inmobiliario - Cómo usarlo
B4: Las hojas
B5: Panel | C5: Resumen: leads por canal, % de colegas, costo por lead calificado, acciones vencidas y embudo.
B6: Leads | C6: Una fila por persona que te consulta. Es la hoja principal.
B7: Seguimiento | C7: Una fila por cada contacto (WhatsApp, llamada, tasación). Actualiza solo el 'Último contacto' del lead.
B8: Listas | C8: Las opciones de los menús desplegables y el % de comisión por tipo de lead. Podés agregar opciones.
B10: Día a día
B11: 1. Entra un lead | C11: Cargalo en Leads con el 'Próximo N° libre' que muestra el Panel. Completá sí o sí Fecha, Nombre, Teléfono, Tipo, Origen y Etapa.
B12: 2. Lo contactás | C12: Anotalo en Seguimiento con el N° del lead. Actualizá Etapa, Próxima acción y su fecha en Leads.
B13: 3. Es un colega | C13: Tipo = 'Colega inmobiliario', Etapa = 'Descartado', Motivo = 'Es colega inmobiliario'. El Panel calcula el % de colegas por canal.
B14: 4. Cada mañana | C14: Filtrá la columna Alerta de Leads por 'Vencida' y 'Hoy'.
B16: Etapas
B17: 1 a 8 | C17: Avance real: Nuevo → Contactado → Calificado → Tasación/visita agendada → Tasación/visita hecha → Captada / oferta → Reservado → Cerrado.
B18: Calificado | C18: Definilo vos y respetalo. Sugerencia: es dueño o comprador real, está en tu zona y tiene un plazo de menos de 12 meses.
B19: Perdido | C19: Era un cliente posible pero no se dio (eligió a otro, no responde, etc.).
B20: Descartado | C20: Nunca fue un cliente posible: colega, spam, datos falsos.
B22: Una vez por semana: informarle a Meta y Google qué leads sirvieron
B23: Para qué | C23: Si Meta y Google saben qué leads llegaron a tasación o cierre, aprenden a buscar gente parecida y a evitar colegas y curiosos.
B24: Cómo | C24: En Leads, filtrá 'Evento a informar' (no vacío) y '¿Informado a Meta/Google?' = No. Subí esos leads (email, teléfono, nombre, ID lead Meta o GCLID, evento y fecha) en el Administrador de eventos de Meta y en Conversiones de Google Ads. Después marcá '¿Informado?' = Sí.
B25: Necesitás | C25: ID lead Meta: viene en la descarga de leads de los formularios de Meta. GCLID: tu web tiene que guardarlo en un campo oculto del formulario.
B27: Colores
B28: Celda amarilla | C28: Dato que cargás vos en Panel y Listas (fechas, inversión, % comisión).
B29: Columna gris | C29: Automática (fórmula). No la escribas encima.
B30: Alerta roja / amarilla | C30: Acción vencida / para hoy.
B31: Fila gris clara | C31: Lead perdido o descartado.
B32: Fila verde | C32: Operación cerrada.
B34: Antes de empezar
B35: Ejemplos | C35: Las filas 2 a 4 de Leads y de Seguimiento son ejemplos. Eliminalas (clic derecho → Eliminar → Filas de la tabla); no borres solo el contenido porque perderías las fórmulas.
B36: Comisión | C36: Los % de la hoja Listas son de ejemplo. Ajustalos a lo que cobrás.
B37: Capacidad | C37: Leads tiene fórmulas listas para 2.000 filas y Seguimiento para 1.000. Si te pasás, copiá la última fila hacia abajo.
B38: Datos personales | C38: Cargá solo datos que la persona te dio y registrá si aceptó que la contactes (Ley 25.326). No compartas el archivo con terceros.
B39: OneDrive | C39: Funciona en Excel de escritorio y en Excel online. Subilo a OneDrive y abrilo desde ahí.

Sheet Panel
B1: CRM Inmobiliario - Panel
B2: Cambiá las fechas (celdas amarillas) para ver otro período. Las tablas por canal y por tipo cuentan leads ingresados en ese período.
B4: Desde | C4: 46296 | E4: Próximo N° libre | G4: =MAX(Leads!$A$2:$A$5001)+1 -> 4
B5: Hasta | C5: 46326
B7: Resumen del período | E7: Hoy (todas las fechas)
B8: Leads ingresados | C8: =COUNTIFS(Leads!$B$2:$B$5001,">="&$C$4,Leads!$B$2:$B$5001,"<="&$C$5) -> 3 | E8: Acciones vencidas | H8: =COUNTIF(Leads!$W$2:$W$5001,"Vencida") -> 1
B9: Calificados (etapa 3 a 8) | C9: =COUNTIFS(Leads!$B$2:$B$5001,">="&$C$4,Leads!$B$2:$B$5001,"<="&$C$5,Leads!$AG$2:$AG$5001,">=3",Leads!$AG$2:$AG$5001,"<=8") -> 2 | E9: Acciones para hoy | H9: =COUNTIF(Leads!$W$2:$W$5001,"Hoy") -> 0
B10: Tasaciones / visitas (etapa 4 a 8) | C10: =COUNTIFS(Leads!$B$2:$B$5001,">="&$C$4,Leads!$B$2:$B$5001,"<="&$C$5,Leads!$AG$2:$AG$5001,">=4",Leads!$AG$2:$AG$5001,"<=8") -> 1 | E10: Leads activos (etapa 1 a 7) | H10: =COUNTIFS(Leads!$AG$2:$AG$5001,">=1",Leads!$AG$2:$AG$5001,"<=7") -> 2
B11: Cierres | C11: =COUNTIFS(Leads!$B$2:$B$5001,">="&$C$4,Leads!$B$2:$B$5001,"<="&$C$5,Leads!$AG$2:$AG$5001,8) -> 0 | E11: Comisión estimada en juego (USD) | H11: =SUMIFS(Leads!$Z$2:$Z$5001,Leads!$AG$2:$AG$5001,">=1",Leads!$AG$2:$AG$5001,"<=7") -> 9150
B12: Colegas inmobiliarios | C12: =COUNTIFS(Leads!$B$2:$B$5001,">="&$C$4,Leads!$B$2:$B$5001,"<="&$C$5,Leads!$G$2:$G$5001,"Colega inmobiliario") -> 1
B13: % colegas | C13: =IF(C8=0,"",C12/C8) -> 0.33333333
B14: Inversión en anuncios | C14: =SUM(I19:I30) -> 0
B15: Costo por lead calificado (anuncios) | C15: =IF(C14=0,"",IFERROR(C14/SUMIFS(F19:F30,I19:I30,">0"),""))
B17: Por canal de origen (período)
B18: Origen | C18: Leads | D18: Colegas | E18: % colegas | F18: Calificados | G18: Tasaciones / visitas | H18: Cierres | I18: Inversión ($) | J18: Costo por lead | K18: Costo por calificado | L18: Costo por tasación / visita
B19: =IF(INDEX(Listas!$D$2:$D$50,1)="","",INDEX(Listas!$D$2:$D$50,1)) -> Meta Ads (formulario) | C19: =IF($B19="","",COUNTIFS(Leads!$B$2:$B$5001,">="&$C$4,Leads!$B$2:$B$5001,"<="&$C$5,Leads!$H$2:$H$5001,$B19)) -> 2 | D19: =IF($B19="","",COUNTIFS(Leads!$B$2:$B$5001,">="&$C$4,Leads!$B$2:$B$5001,"<="&$C$5,Leads!$H$2:$H$5001,$B19,Leads!$G$2:$G$5001,"Colega inmobiliario")) -> 1 | E19: =IF(OR($B19="",N(C19)=0),"",D19/C19) -> 0.5 | F19: =IF($B19="","",COUNTIFS(Leads!$B$2:$B$5001,">="&$C$4,Leads!$B$2:$B$5001,"<="&$C$5,Leads!$H$2:$H$5001,$B19,Leads!$AG$2:$AG$5001,">=3",Leads!$AG$2:$AG$5001,"<=8")) -> 1 | G19: =IF($B19="","",COUNTIFS(Leads!$B$2:$B$5001,">="&$C$4,Leads!$B$2:$B$5001,"<="&$C$5,Leads!$H$2:$H$5001,$B19,Leads!$AG$2:$AG$5001,">=4",Leads!$AG$2:$AG$5001,"<=8")) -> 1 | H19: =IF($B19="","",COUNTIFS(Leads!$B$2:$B$5001,">="&$C$4,Leads!$B$2:$B$5001,"<="&$C$5,Leads!$H$2:$H$5001,$B19,Leads!$AG$2:$AG$5001,8)) -> 0 | J19: =IF(OR(N(I19)=0,N(C19)=0),"",I19/C19) | K19: =IF(OR(N(I19)=0,N(F19)=0),"",I19/F19) | L19: =IF(OR(N(I19)=0,N(G19)=0),"",I19/G19)
B20: =IF(INDEX(Listas!$D$2:$D$50,2)="","",INDEX(Listas!$D$2:$D$50,2)) -> Meta Ads (WhatsApp/mensaje) | C20: =IF($B20="","",COUNTIFS(Leads!$B$2:$B$5001,">="&$C$4,Leads!$B$2:$B$5001,"<="&$C$5,Leads!$H$2:$H$5001,$B20)) -> 0 | D20: =IF($B20="","",COUNTIFS(Leads!$B$2:$B$5001,">="&$C$4,Leads!$B$2:$B$5001,"<="&$C$5,Leads!$H$2:$H$5001,$B20,Leads!$G$2:$G$5001,"Colega inmobiliario")) -> 0 | E20: =IF(OR($B20="",N(C20)=0),"",D20/C20) | F20: =IF($B20="","",COUNTIFS(Leads!$B$2:$B$5001,">="&$C$4,Leads!$B$2:$B$5001,"<="&$C$5,Leads!$H$2:$H$5001,$B20,Leads!$AG$2:$AG$5001,">=3",Leads!$AG$2:$AG$5001,"<=8")) -> 0 | G20: =IF($B20="","",COUNTIFS(Leads!$B$2:$B$5001,">="&$C$4,Leads!$B$2:$B$5001,"<="&$C$5,Leads!$H$2:$H$5001,$B20,Leads!$AG$2:$AG$5001,">=4",Leads!$AG$2:$AG$5001,"<=8")) -> 0 | H20: =IF($B20="","",COUNTIFS(Leads!$B$2:$B$5001,">="&$C$4,Leads!$B$2:$B$5001,"<="&$C$5,Leads!$H$2:$H$5001,$B20,Leads!$AG$2:$AG$5001,8)) -> 0 | J20: =IF(OR(N(I20)=0,N(C20)=0),"",I20/C20) | K20: =IF(OR(N(I20)=0,N(F20)=0),"",I20/F20) | L20: =IF(OR(N(I20)=0,N(G20)=0),"",I20/G20)
B21: =IF(INDEX(Listas!$D$2:$D$50,3)="","",INDEX(Listas!$D$2:$D$50,3)) -> Google Ads (búsqueda) | C21: =IF($B21="","",COUNTIFS(Leads!$B$2:$B$5001,">="&$C$4,Leads!$B$2:$B$5001,"<="&$C$5,Leads!$H$2:$H$5001,$B21)) -> 1 | D21: =IF($B21="","",COUNTIFS(Leads!$B$2:$B$5001,">="&$C$4,Leads!$B$2:$B$5001,"<="&$C$5,Leads!$H$2:$H$5001,$B21,Leads!$G$2:$G$5001,"Colega inmobiliario")) -> 0 | E21: =IF(OR($B21="",N(C21)=0),"",D21/C21) -> 0 | F21: =IF($B21="","",COUNTIFS(Leads!$B$2:$B$5001,">="&$C$4,Leads!$B$2:$B$5001,"<="&$C$5,Leads!$H$2:$H$5001,$B21,Leads!$AG$2:$AG$5001,">=3",Leads!$AG$2:$AG$5001,"<=8")) -> 1 | G21: =IF($B21="","",COUNTIFS(Leads!$B$2:$B$5001,">="&$C$4,Leads!$B$2:$B$5001,"<="&$C$5,Leads!$H$2:$H$5001,$B21,Leads!$AG$2:$AG$5001,">=4",Leads!$AG$2:$AG$5001,"<=8")) -> 0 | H21: =IF($B21="","",COUNTIFS(Leads!$B$2:$B$5001,">="&$C$4,Leads!$B$2:$B$5001,"<="&$C$5,Leads!$H$2:$H$5001,$B21,Leads!$AG$2:$AG$5001,8)) -> 0 | J21: =IF(OR(N(I21)=0,N(C21)=0),"",I21/C21) | K21: =IF(OR(N(I21)=0,N(F21)=0),"",I21/F21) | L21: =IF(OR(N(I21)=0,N(G21)=0),"",I21/G21)
B22: =IF(INDEX(Listas!$D$2:$D$50,4)="","",INDEX(Listas!$D$2:$D$50,4)) -> Instagram orgánico | C22: =IF($B22="","",COUNTIFS(Leads!$B$2:$B$5001,">="&$C$4,Leads!$B$2:$B$5001,"<="&$C$5,Leads!$H$2:$H$5001,$B22)) -> 0 | D22: =IF($B22="","",COUNTIFS(Leads!$B$2:$B$5001,">="&$C$4,Leads!$B$2:$B$5001,"<="&$C$5,Leads!$H$2:$H$5001,$B22,Leads!$G$2:$G$5001,"Colega inmobiliario")) -> 0 | E22: =IF(OR($B22="",N(C22)=0),"",D22/C22) | F22: =IF($B22="","",COUNTIFS(Leads!$B$2:$B$5001,">="&$C$4,Leads!$B$2:$B$5001,"<="&$C$5,Leads!$H$2:$H$5001,$B22,Leads!$AG$2:$AG$5001,">=3",Leads!$AG$2:$AG$5001,"<=8")) -> 0 | G22: =IF($B22="","",COUNTIFS(Leads!$B$2:$B$5001,">="&$C$4,Leads!$B$2:$B$5001,"<="&$C$5,Leads!$H$2:$H$5001,$B22,Leads!$AG$2:$AG$5001,">=4",Leads!$AG$2:$AG$5001,"<=8")) -> 0 | H22: =IF($B22="","",COUNTIFS(Leads!$B$2:$B$5001,">="&$C$4,Leads!$B$2:$B$5001,"<="&$C$5,Leads!$H$2:$H$5001,$B22,Leads!$AG$2:$AG$5001,8)) -> 0 | J22: =IF(OR(N(I22)=0,N(C22)=0),"",I22/C22) | K22: =IF(OR(N(I22)=0,N(F22)=0),"",I22/F22) | L22: =IF(OR(N(I22)=0,N(G22)=0),"",I22/G22)
B23: =IF(INDEX(Listas!$D$2:$D$50,5)="","",INDEX(Listas!$D$2:$D$50,5)) -> Facebook orgánico | C23: =IF($B23="","",COUNTIFS(Leads!$B$2:$B$5001,">="&$C$4,Leads!$B$2:$B$5001,"<="&$C$5,Leads!$H$2:$H$5001,$B23)) -> 0 | D23: =IF($B23="","",COUNTIFS(Leads!$B$2:$B$5001,">="&$C$4,Leads!$B$2:$B$5001,"<="&$C$5,Leads!$H$2:$H$5001,$B23,Leads!$G$2:$G$5001,"Colega inmobiliario")) -> 0 | E23: =IF(OR($B23="",N(C23)=0),"",D23/C23) | F23: =IF($B23="","",COUNTIFS(Leads!$B$2:$B$5001,">="&$C$4,Leads!$B$2:$B$5001,"<="&$C$5,Leads!$H$2:$H$5001,$B23,Leads!$AG$2:$AG$5001,">=3",Leads!$AG$2:$AG$5001,"<=8")) -> 0 | G23: =IF($B23="","",COUNTIFS(Leads!$B$2:$B$5001,">="&$C$4,Leads!$B$2:$B$5001,"<="&$C$5,Leads!$H$2:$H$5001,$B23,Leads!$AG$2:$AG$5001,">=4",Leads!$AG$2:$AG$5001,"<=8")) -> 0 | H23: =IF($B23="","",COUNTIFS(Leads!$B$2:$B$5001,">="&$C$4,Leads!$B$2:$B$5001,"<="&$C$5,Leads!$H$2:$H$5001,$B23,Leads!$AG$2:$AG$5001,8)) -> 0 | J23: =IF(OR(N(I23)=0,N(C23)=0),"",I23/C23) | K23: =IF(OR(N(I23)=0,N(F23)=0),"",I23/F23) | L23: =IF(OR(N(I23)=0,N(G23)=0),"",I23/G23)
B24: =IF(INDEX(Listas!$D$2:$D$50,6)="","",INDEX(Listas!$D$2:$D$50,6)) -> Portales (Zonaprop/Argenprop/ML) | C24: =IF($B24="","",COUNTIFS(Leads!$B$2:$B$5001,">="&$C$4,Leads!$B$2:$B$5001,"<="&$C$5,Leads!$H$2:$H$5001,$B24)) -> 0 | D24: =IF($B24="","",COUNTIFS(Leads!$B$2:$B$5001,">="&$C$4,Leads!$B$2:$B$5001,"<="&$C$5,Leads!$H$2:$H$5001,$B24,Leads!$G$2:$G$5001,"Colega inmobiliario")) -> 0 | E24: =IF(OR($B24="",N(C24)=0),"",D24/C24) | F24: =IF($B24="","",COUNTIFS(Leads!$B$2:$B$5001,">="&$C$4,Leads!$B$2:$B$5001,"<="&$C$5,Leads!$H$2:$H$5001,$B24,Leads!$AG$2:$AG$5001,">=3",Leads!$AG$2:$AG$5001,"<=8")) -> 0 | G24: =IF($B24="","",COUNTIFS(Leads!$B$2:$B$5001,">="&$C$4,Leads!$B$2:$B$5001,"<="&$C$5,Leads!$H$2:$H$5001,$B24,Leads!$AG$2:$AG$5001,">=4",Leads!$AG$2:$AG$5001,"<=8")) -> 0 | H24: =IF($B24="","",COUNTIFS(Leads!$B$2:$B$5001,">="&$C$4,Leads!$B$2:$B$5001,"<="&$C$5,Leads!$H$2:$H$5001,$B24,Leads!$AG$2:$AG$5001,8)) -> 0 | J24: =IF(OR(N(I24)=0,N(C24)=0),"",I24/C24) | K24: =IF(OR(N(I24)=0,N(F24)=0),"",I24/F24) | L24: =IF(OR(N(I24)=0,N(G24)=0),"",I24/G24)
B25: =IF(INDEX(Listas!$D$2:$D$50,7)="","",INDEX(Listas!$D$2:$D$50,7)) -> Web propia | C25: =IF($B25="","",COUNTIFS(Leads!$B$2:$B$5001,">="&$C$4,Leads!$B$2:$B$5001,"<="&$C$5,Leads!$H$2:$H$5001,$B25)) -> 0 | D25: =IF($B25="","",COUNTIFS(Leads!$B$2:$B$5001,">="&$C$4,Leads!$B$2:$B$5001,"<="&$C$5,Leads!$H$2:$H$5001,$B25,Leads!$G$2:$G$5001,"Colega inmobiliario")) -> 0 | E25: =IF(OR($B25="",N(C25)=0),"",D25/C25) | F25: =IF($B25="","",COUNTIFS(Leads!$B$2:$B$5001,">="&$C$4,Leads!$B$2:$B$5001,"<="&$C$5,Leads!$H$2:$H$5001,$B25,Leads!$AG$2:$AG$5001,">=3",Leads!$AG$2:$AG$5001,"<=8")) -> 0 | G25: =IF($B25="","",COUNTIFS(Leads!$B$2:$B$5001,">="&$C$4,Leads!$B$2:$B$5001,"<="&$C$5,Leads!$H$2:$H$5001,$B25,Leads!$AG$2:$AG$5001,">=4",Leads!$AG$2:$AG$5001,"<=8")) -> 0 | H25: =IF($B25="","",COUNTIFS(Leads!$B$2:$B$5001,">="&$C$4,Leads!$B$2:$B$5001,"<="&$C$5,Leads!$H$2:$H$5001,$B25,Leads!$AG$2:$AG$5001,8)) -> 0 | J25: =IF(OR(N(I25)=0,N(C25)=0),"",I25/C25) | K25: =IF(OR(N(I25)=0,N(F25)=0),"",I25/F25) | L25: =IF(OR(N(I25)=0,N(G25)=0),"",I25/G25)
B26: =IF(INDEX(Listas!$D$2:$D$50,8)="","",INDEX(Listas!$D$2:$D$50,8)) -> Referido | C26: =IF($B26="","",COUNTIFS(Leads!$B$2:$B$5001,">="&$C$4,Leads!$B$2:$B$5001,"<="&$C$5,Leads!$H$2:$H$5001,$B26)) -> 0 | D26: =IF($B26="","",COUNTIFS(Leads!$B$2:$B$5001,">="&$C$4,Leads!$B$2:$B$5001,"<="&$C$5,Leads!$H$2:$H$5001,$B26,Leads!$G$2:$G$5001,"Colega inmobiliario")) -> 0 | E26: =IF(OR($B26="",N(C26)=0),"",D26/C26) | F26: =IF($B26="","",COUNTIFS(Leads!$B$2:$B$5001,">="&$C$4,Leads!$B$2:$B$5001,"<="&$C$5,Leads!$H$2:$H$5001,$B26,Leads!$AG$2:$AG$5001,">=3",Leads!$AG$2:$AG$5001,"<=8")) -> 0 | G26: =IF($B26="","",COUNTIFS(Leads!$B$2:$B$5001,">="&$C$4,Leads!$B$2:$B$5001,"<="&$C$5,Leads!$H$2:$H$5001,$B26,Leads!$AG$2:$AG$5001,">=4",Leads!$AG$2:$AG$5001,"<=8")) -> 0 | H26: =IF($B26="","",COUNTIFS(Leads!$B$2:$B$5001,">="&$C$4,Leads!$B$2:$B$5001,"<="&$C$5,Leads!$H$2:$H$5001,$B26,Leads!$AG$2:$AG$5001,8)) -> 0 | J26: =IF(OR(N(I26)=0,N(C26)=0),"",I26/C26) | K26: =IF(OR(N(I26)=0,N(F26)=0),"",I26/F26) | L26: =IF(OR(N(I26)=0,N(G26)=0),"",I26/G26)
B27: =IF(INDEX(Listas!$D$2:$D$50,9)="","",INDEX(Listas!$D$2:$D$50,9)) -> Cartel en propiedad | C27: =IF($B27="","",COUNTIFS(Leads!$B$2:$B$5001,">="&$C$4,Leads!$B$2:$B$5001,"<="&$C$5,Leads!$H$2:$H$5001,$B27)) -> 0 | D27: =IF($B27="","",COUNTIFS(Leads!$B$2:$B$5001,">="&$C$4,Leads!$B$2:$B$5001,"<="&$C$5,Leads!$H$2:$H$5001,$B27,Leads!$G$2:$G$5001,"Colega inmobiliario")) -> 0 | E27: =IF(OR($B27="",N(C27)=0),"",D27/C27) | F27: =IF($B27="","",COUNTIFS(Leads!$B$2:$B$5001,">="&$C$4,Leads!$B$2:$B$5001,"<="&$C$5,Leads!$H$2:$H$5001,$B27,Leads!$AG$2:$AG$5001,">=3",Leads!$AG$2:$AG$5001,"<=8")) -> 0 | G27: =IF($B27="","",COUNTIFS(Leads!$B$2:$B$5001,">="&$C$4,Leads!$B$2:$B$5001,"<="&$C$5,Leads!$H$2:$H$5001,$B27,Leads!$AG$2:$AG$5001,">=4",Leads!$AG$2:$AG$5001,"<=8")) -> 0 | H27: =IF($B27="","",COUNTIFS(Leads!$B$2:$B$5001,">="&$C$4,Leads!$B$2:$B$5001,"<="&$C$5,Leads!$H$2:$H$5001,$B27,Leads!$AG$2:$AG$5001,8)) -> 0 | J27: =IF(OR(N(I27)=0,N(C27)=0),"",I27/C27) | K27: =IF(OR(N(I27)=0,N(F27)=0),"",I27/F27) | L27: =IF(OR(N(I27)=0,N(G27)=0),"",I27/G27)
B28: =IF(INDEX(Listas!$D$2:$D$50,10)="","",INDEX(Listas!$D$2:$D$50,10)) -> Base propia / ex clientes | C28: =IF($B28="","",COUNTIFS(Leads!$B$2:$B$5001,">="&$C$4,Leads!$B$2:$B$5001,"<="&$C$5,Leads!$H$2:$H$5001,$B28)) -> 0 | D28: =IF($B28="","",COUNTIFS(Leads!$B$2:$B$5001,">="&$C$4,Leads!$B$2:$B$5001,"<="&$C$5,Leads!$H$2:$H$5001,$B28,Leads!$G$2:$G$5001,"Colega inmobiliario")) -> 0 | E28: =IF(OR($B28="",N(C28)=0),"",D28/C28) | F28: =IF($B28="","",COUNTIFS(Leads!$B$2:$B$5001,">="&$C$4,Leads!$B$2:$B$5001,"<="&$C$5,Leads!$H$2:$H$5001,$B28,Leads!$AG$2:$AG$5001,">=3",Leads!$AG$2:$AG$5001,"<=8")) -> 0 | G28: =IF($B28="","",COUNTIFS(Leads!$B$2:$B$5001,">="&$C$4,Leads!$B$2:$B$5001,"<="&$C$5,Leads!$H$2:$H$5001,$B28,Leads!$AG$2:$AG$5001,">=4",Leads!$AG$2:$AG$5001,"<=8")) -> 0 | H28: =IF($B28="","",COUNTIFS(Leads!$B$2:$B$5001,">="&$C$4,Leads!$B$2:$B$5001,"<="&$C$5,Leads!$H$2:$H$5001,$B28,Leads!$AG$2:$AG$5001,8)) -> 0 | J28: =IF(OR(N(I28)=0,N(C28)=0),"",I28/C28) | K28: =IF(OR(N(I28)=0,N(F28)=0),"",I28/F28) | L28: =IF(OR(N(I28)=0,N(G28)=0),"",I28/G28)
B29: =IF(INDEX(Listas!$D$2:$D$50,11)="","",INDEX(Listas!$D$2:$D$50,11)) -> Otro | C29: =IF($B29="","",COUNTIFS(Leads!$B$2:$B$5001,">="&$C$4,Leads!$B$2:$B$5001,"<="&$C$5,Leads!$H$2:$H$5001,$B29)) -> 0 | D29: =IF($B29="","",COUNTIFS(Leads!$B$2:$B$5001,">="&$C$4,Leads!$B$2:$B$5001,"<="&$C$5,Leads!$H$2:$H$5001,$B29,Leads!$G$2:$G$5001,"Colega inmobiliario")) -> 0 | E29: =IF(OR($B29="",N(C29)=0),"",D29/C29) | F29: =IF($B29="","",COUNTIFS(Leads!$B$2:$B$5001,">="&$C$4,Leads!$B$2:$B$5001,"<="&$C$5,Leads!$H$2:$H$5001,$B29,Leads!$AG$2:$AG$5001,">=3",Leads!$AG$2:$AG$5001,"<=8")) -> 0 | G29: =IF($B29="","",COUNTIFS(Leads!$B$2:$B$5001,">="&$C$4,Leads!$B$2:$B$5001,"<="&$C$5,Leads!$H$2:$H$5001,$B29,Leads!$AG$2:$AG$5001,">=4",Leads!$AG$2:$AG$5001,"<=8")) -> 0 | H29: =IF($B29="","",COUNTIFS(Leads!$B$2:$B$5001,">="&$C$4,Leads!$B$2:$B$5001,"<="&$C$5,Leads!$H$2:$H$5001,$B29,Leads!$AG$2:$AG$5001,8)) -> 0 | J29: =IF(OR(N(I29)=0,N(C29)=0),"",I29/C29) | K29: =IF(OR(N(I29)=0,N(F29)=0),"",I29/F29) | L29: =IF(OR(N(I29)=0,N(G29)=0),"",I29/G29)
B30: =IF(INDEX(Listas!$D$2:$D$50,12)="","",INDEX(Listas!$D$2:$D$50,12)) | C30: =IF($B30="","",COUNTIFS(Leads!$B$2:$B$5001,">="&$C$4,Leads!$B$2:$B$5001,"<="&$C$5,Leads!$H$2:$H$5001,$B30)) | D30: =IF($B30="","",COUNTIFS(Leads!$B$2:$B$5001,">="&$C$4,Leads!$B$2:$B$5001,"<="&$C$5,Leads!$H$2:$H$5001,$B30,Leads!$G$2:$G$5001,"Colega inmobiliario")) | E30: =IF(OR($B30="",N(C30)=0),"",D30/C30) | F30: =IF($B30="","",COUNTIFS(Leads!$B$2:$B$5001,">="&$C$4,Leads!$B$2:$B$5001,"<="&$C$5,Leads!$H$2:$H$5001,$B30,Leads!$AG$2:$AG$5001,">=3",Leads!$AG$2:$AG$5001,"<=8")) | G30: =IF($B30="","",COUNTIFS(Leads!$B$2:$B$5001,">="&$C$4,Leads!$B$2:$B$5001,"<="&$C$5,Leads!$H$2:$H$5001,$B30,Leads!$AG$2:$AG$5001,">=4",Leads!$AG$2:$AG$5001,"<=8")) | H30: =IF($B30="","",COUNTIFS(Leads!$B$2:$B$5001,">="&$C$4,Leads!$B$2:$B$5001,"<="&$C$5,Leads!$H$2:$H$5001,$B30,Leads!$AG$2:$AG$5001,8)) | J30: =IF(OR(N(I30)=0,N(C30)=0),"",I30/C30) | K30: =IF(OR(N(I30)=0,N(F30)=0),"",I30/F30) | L30: =IF(OR(N(I30)=0,N(G30)=0),"",I30/G30)
B31: % colegas en rojo = 20% o más (umbral orientativo). Si un canal trae muchos, revisá segmentación, anuncio y formulario de ese canal.
B33: Por tipo de lead (período)
B34: Tipo de lead | C34: Leads | D34: Calificados | E34: Tasaciones / visitas | F34: Cierres
B35: =IF(INDEX(Listas!$A$2:$A$50,1)="","",INDEX(Listas!$A$2:$A$50,1)) -> Vendedor | C35: =IF($B35="","",COUNTIFS(Leads!$B$2:$B$5001,">="&$C$4,Leads!$B$2:$B$5001,"<="&$C$5,Leads!$G$2:$G$5001,$B35)) -> 1 | D35: =IF($B35="","",COUNTIFS(Leads!$B$2:$B$5001,">="&$C$4,Leads!$B$2:$B$5001,"<="&$C$5,Leads!$G$2:$G$5001,$B35,Leads!$AG$2:$AG$5001,">=3",Leads!$AG$2:$AG$5001,"<=8")) -> 1 | E35: =IF($B35="","",COUNTIFS(Leads!$B$2:$B$5001,">="&$C$4,Leads!$B$2:$B$5001,"<="&$C$5,Leads!$G$2:$G$5001,$B35,Leads!$AG$2:$AG$5001,">=4",Leads!$AG$2:$AG$5001,"<=8")) -> 1 | F35: =IF($B35="","",COUNTIFS(Leads!$B$2:$B$5001,">="&$C$4,Leads!$B$2:$B$5001,"<="&$C$5,Leads!$G$2:$G$5001,$B35,Leads!$AG$2:$AG$5001,8)) -> 0
B36: =IF(INDEX(Listas!$A$2:$A$50,2)="","",INDEX(Listas!$A$2:$A$50,2)) -> Comprador | C36: =IF($B36="","",COUNTIFS(Leads!$B$2:$B$5001,">="&$C$4,Leads!$B$2:$B$5001,"<="&$C$5,Leads!$G$2:$G$5001,$B36)) -> 1 | D36: =IF($B36="","",COUNTIFS(Leads!$B$2:$B$5001,">="&$C$4,Leads!$B$2:$B$5001,"<="&$C$5,Leads!$G$2:$G$5001,$B36,Leads!$AG$2:$AG$5001,">=3",Leads!$AG$2:$AG$5001,"<=8")) -> 1 | E36: =IF($B36="","",COUNTIFS(Leads!$B$2:$B$5001,">="&$C$4,Leads!$B$2:$B$5001,"<="&$C$5,Leads!$G$2:$G$5001,$B36,Leads!$AG$2:$AG$5001,">=4",Leads!$AG$2:$AG$5001,"<=8")) -> 0 | F36: =IF($B36="","",COUNTIFS(Leads!$B$2:$B$5001,">="&$C$4,Leads!$B$2:$B$5001,"<="&$C$5,Leads!$G$2:$G$5001,$B36,Leads!$AG$2:$AG$5001,8)) -> 0
B37: =IF(INDEX(Listas!$A$2:$A$50,3)="","",INDEX(Listas!$A$2:$A$50,3)) -> Inversor | C37: =IF($B37="","",COUNTIFS(Leads!$B$2:$B$5001,">="&$C$4,Leads!$B$2:$B$5001,"<="&$C$5,Leads!$G$2:$G$5001,$B37)) -> 0 | D37: =IF($B37="","",COUNTIFS(Leads!$B$2:$B$5001,">="&$C$4,Leads!$B$2:$B$5001,"<="&$C$5,Leads!$G$2:$G$5001,$B37,Leads!$AG$2:$AG$5001,">=3",Leads!$AG$2:$AG$5001,"<=8")) -> 0 | E37: =IF($B37="","",COUNTIFS(Leads!$B$2:$B$5001,">="&$C$4,Leads!$B$2:$B$5001,"<="&$C$5,Leads!$G$2:$G$5001,$B37,Leads!$AG$2:$AG$5001,">=4",Leads!$AG$2:$AG$5001,"<=8")) -> 0 | F37: =IF($B37="","",COUNTIFS(Leads!$B$2:$B$5001,">="&$C$4,Leads!$B$2:$B$5001,"<="&$C$5,Leads!$G$2:$G$5001,$B37,Leads!$AG$2:$AG$5001,8)) -> 0
B38: =IF(INDEX(Listas!$A$2:$A$50,4)="","",INDEX(Listas!$A$2:$A$50,4)) -> Propietario (alquiler) | C38: =IF($B38="","",COUNTIFS(Leads!$B$2:$B$5001,">="&$C$4,Leads!$B$2:$B$5001,"<="&$C$5,Leads!$G$2:$G$5001,$B38)) -> 0 | D38: =IF($B38="","",COUNTIFS(Leads!$B$2:$B$5001,">="&$C$4,Leads!$B$2:$B$5001,"<="&$C$5,Leads!$G$2:$G$5001,$B38,Leads!$AG$2:$AG$5001,">=3",Leads!$AG$2:$AG$5001,"<=8")) -> 0 | E38: =IF($B38="","",COUNTIFS(Leads!$B$2:$B$5001,">="&$C$4,Leads!$B$2:$B$5001,"<="&$C$5,Leads!$G$2:$G$5001,$B38,Leads!$AG$2:$AG$5001,">=4",Leads!$AG$2:$AG$5001,"<=8")) -> 0 | F38: =IF($B38="","",COUNTIFS(Leads!$B$2:$B$5001,">="&$C$4,Leads!$B$2:$B$5001,"<="&$C$5,Leads!$G$2:$G$5001,$B38,Leads!$AG$2:$AG$5001,8)) -> 0
B39: =IF(INDEX(Listas!$A$2:$A$50,5)="","",INDEX(Listas!$A$2:$A$50,5)) -> Inquilino | C39: =IF($B39="","",COUNTIFS(Leads!$B$2:$B$5001,">="&$C$4,Leads!$B$2:$B$5001,"<="&$C$5,Leads!$G$2:$G$5001,$B39)) -> 0 | D39: =IF($B39="","",COUNTIFS(Leads!$B$2:$B$5001,">="&$C$4,Leads!$B$2:$B$5001,"<="&$C$5,Leads!$G$2:$G$5001,$B39,Leads!$AG$2:$AG$5001,">=3",Leads!$AG$2:$AG$5001,"<=8")) -> 0 | E39: =IF($B39="","",COUNTIFS(Leads!$B$2:$B$5001,">="&$C$4,Leads!$B$2:$B$5001,"<="&$C$5,Leads!$G$2:$G$5001,$B39,Leads!$AG$2:$AG$5001,">=4",Leads!$AG$2:$AG$5001,"<=8")) -> 0 | F39: =IF($B39="","",COUNTIFS(Leads!$B$2:$B$5001,">="&$C$4,Leads!$B$2:$B$5001,"<="&$C$5,Leads!$G$2:$G$5001,$B39,Leads!$AG$2:$AG$5001,8)) -> 0
B40: =IF(INDEX(Listas!$A$2:$A$50,6)="","",INDEX(Listas!$A$2:$A$50,6)) -> Colega inmobiliario | C40: =IF($B40="","",COUNTIFS(Leads!$B$2:$B$5001,">="&$C$4,Leads!$B$2:$B$5001,"<="&$C$5,Leads!$G$2:$G$5001,$B40)) -> 1 | D40: =IF($B40="","",COUNTIFS(Leads!$B$2:$B$5001,">="&$C$4,Leads!$B$2:$B$5001,"<="&$C$5,Leads!$G$2:$G$5001,$B40,Leads!$AG$2:$AG$5001,">=3",Leads!$AG$2:$AG$5001,"<=8")) -> 0 | E40: =IF($B40="","",COUNTIFS(Leads!$B$2:$B$5001,">="&$C$4,Leads!$B$2:$B$5001,"<="&$C$5,Leads!$G$2:$G$5001,$B40,Leads!$AG$2:$AG$5001,">=4",Leads!$AG$2:$AG$5001,"<=8")) -> 0 | F40: =IF($B40="","",COUNTIFS(Leads!$B$2:$B$5001,">="&$C$4,Leads!$B$2:$B$5001,"<="&$C$5,Leads!$G$2:$G$5001,$B40,Leads!$AG$2:$AG$5001,8)) -> 0
B41: =IF(INDEX(Listas!$A$2:$A$50,7)="","",INDEX(Listas!$A$2:$A$50,7)) -> Spam / datos falsos | C41: =IF($B41="","",COUNTIFS(Leads!$B$2:$B$5001,">="&$C$4,Leads!$B$2:$B$5001,"<="&$C$5,Leads!$G$2:$G$5001,$B41)) -> 0 | D41: =IF($B41="","",COUNTIFS(Leads!$B$2:$B$5001,">="&$C$4,Leads!$B$2:$B$5001,"<="&$C$5,Leads!$G$2:$G$5001,$B41,Leads!$AG$2:$AG$5001,">=3",Leads!$AG$2:$AG$5001,"<=8")) -> 0 | E41: =IF($B41="","",COUNTIFS(Leads!$B$2:$B$5001,">="&$C$4,Leads!$B$2:$B$5001,"<="&$C$5,Leads!$G$2:$G$5001,$B41,Leads!$AG$2:$AG$5001,">=4",Leads!$AG$2:$AG$5001,"<=8")) -> 0 | F41: =IF($B41="","",COUNTIFS(Leads!$B$2:$B$5001,">="&$C$4,Leads!$B$2:$B$5001,"<="&$C$5,Leads!$G$2:$G$5001,$B41,Leads!$AG$2:$AG$5001,8)) -> 0
B42: =IF(INDEX(Listas!$A$2:$A$50,8)="","",INDEX(Listas!$A$2:$A$50,8)) | C42: =IF($B42="","",COUNTIFS(Leads!$B$2:$B$5001,">="&$C$4,Leads!$B$2:$B$5001,"<="&$C$5,Leads!$G$2:$G$5001,$B42)) | D42: =IF($B42="","",COUNTIFS(Leads!$B$2:$B$5001,">="&$C$4,Leads!$B$2:$B$5001,"<="&$C$5,Leads!$G$2:$G$5001,$B42,Leads!$AG$2:$AG$5001,">=3",Leads!$AG$2:$AG$5001,"<=8")) | E42: =IF($B42="","",COUNTIFS(Leads!$B$2:$B$5001,">="&$C$4,Leads!$B$2:$B$5001,"<="&$C$5,Leads!$G$2:$G$5001,$B42,Leads!$AG$2:$AG$5001,">=4",Leads!$AG$2:$AG$5001,"<=8")) | F42: =IF($B42="","",COUNTIFS(Leads!$B$2:$B$5001,">="&$C$4,Leads!$B$2:$B$5001,"<="&$C$5,Leads!$G$2:$G$5001,$B42,Leads!$AG$2:$AG$5001,8))
B43: =IF(INDEX(Listas!$A$2:$A$50,9)="","",INDEX(Listas!$A$2:$A$50,9)) | C43: =IF($B43="","",COUNTIFS(Leads!$B$2:$B$5001,">="&$C$4,Leads!$B$2:$B$5001,"<="&$C$5,Leads!$G$2:$G$5001,$B43)) | D43: =IF($B43="","",COUNTIFS(Leads!$B$2:$B$5001,">="&$C$4,Leads!$B$2:$B$5001,"<="&$C$5,Leads!$G$2:$G$5001,$B43,Leads!$AG$2:$AG$5001,">=3",Leads!$AG$2:$AG$5001,"<=8")) | E43: =IF($B43="","",COUNTIFS(Leads!$B$2:$B$5001,">="&$C$4,Leads!$B$2:$B$5001,"<="&$C$5,Leads!$G$2:$G$5001,$B43,Leads!$AG$2:$AG$5001,">=4",Leads!$AG$2:$AG$5001,"<=8")) | F43: =IF($B43="","",COUNTIFS(Leads!$B$2:$B$5001,">="&$C$4,Leads!$B$2:$B$5001,"<="&$C$5,Leads!$G$2:$G$5001,$B43,Leads!$AG$2:$AG$5001,8))
B45: Embudo actual (todos los leads, sin filtro de fecha)
...

Sheet Leads
A1: N° | B1: Fecha ingreso | C1: Nombre | D1: Apellido | E1: Teléfono / WhatsApp | F1: Email | G1: Tipo de lead | H1: Origen | I1: Campaña | J1: Anuncio / palabra clave | K1: Zona / barrio | L1: Tipo de propiedad | M1: Ambientes | N1: Dirección (vendedores) | O1: Valor estimado (USD) | P1: Plazo | Q1: Forma de pago (compradores) | R1: Etapa | S1: Temperatura | T1: Motivo pérdida / descarte | U1: Próxima acción | V1: Fecha próxima acción | W1: Alerta | X1: Último contacto | Y1: Días desde ingreso | Z1: Comisión estimada (USD) | AA1: Consentimiento de contacto | AB1: ID lead Meta | AC1: GCLID (Google) | AD1: Evento a informar | AE1: ¿Informado a Meta/Google? | AF1: Notas | AG1: N° etapa
A2: 1 | B2: 46298 | C2: Laura | D2: Gómez | E2: +54 9 11 5555-0101 | F2: laura.gomez@example.com | G2: Vendedor | H2: Meta Ads (formulario) | I2: Vendedores - Caballito | J2: Video tasación sin cargo | K2: Caballito | L2: Departamento | M2: 3 | N2: Av. Ejemplo 1234 5°B | O2: 145000 | P2: 3 a 6 meses | R2: 4. Tasación/visita agendada | S2: Caliente | U2: Tasar el departamento | V2: 46309 | W2: =IF(OR(V2="",AG2>=8),"",IF(V2<TODAY(),"Vencida",IF(V2=TODAY(),"Hoy",""))) | X2: =IF(A2="","",IF(COUNTIF(Seguimiento!$B$2:$B$5001,A2)=0,"",_xlfn.MAXIFS(Seguimiento!$A$2:$A$5001,Seguimiento!$B$2:$B$5001,A2))) -> 46300 | Y2: =IF(B2="","",TODAY()-B2) -> 7 | Z2: =IF(OR(O2="",G2=""),"",O2*IFERROR(INDEX(Listas!$B$2:$B$50,MATCH(G2,Listas!$A$2:$A$50,0)),0)) -> 4350 | AA2: Sí | AB2: 000000000000001 | AD2: =IF(OR(LEFT(H2,4)="Meta",LEFT(H2,6)="Google"),IF(AG2=3,"Lead calificado",IF(OR(AG2=4,AG2=5),"Tasación/visita",IF(OR(AG2=6,AG2=7),"Captación/oferta",IF(AG2=8,"Cierre","")))),"") -> Tasación/visita | AE2: No | AF2: EJEMPLO - borrá esta fila | AG2: =IF(R2="",0,IFERROR(MATCH(R2,Listas!$L$2:$L$50,0),0)) -> 4
A3: 2 | B3: 46301 | C3: Martín | D3: Pérez | E3: +54 9 11 5555-0202 | F3: martin.perez@example.com | G3: Comprador | H3: Google Ads (búsqueda) | I3: Compradores - Palermo | J3: comprar departamento 2 ambientes palermo | K3: Palermo | L3: Departamento | M3: 2 | O3: 120000 | P3: Inmediato (0-3 meses) | Q3: Crédito hipotecario | R3: 3. Calificado | S3: Tibio | U3: Mandar 3 opciones de 2 ambientes | V3: 46304 | W3: =IF(OR(V3="",AG3>=8),"",IF(V3<TODAY(),"Vencida",IF(V3=TODAY(),"Hoy",""))) -> Vencida | X3: =IF(A3="","",IF(COUNTIF(Seguimiento!$B$2:$B$5001,A3)=0,"",_xlfn.MAXIFS(Seguimiento!$A$2:$A$5001,Seguimiento!$B$2:$B$5001,A3))) -> 46302 | Y3: =IF(B3="","",TODAY()-B3) -> 4 | Z3: =IF(OR(O3="",G3=""),"",O3*IFERROR(INDEX(Listas!$B$2:$B$50,MATCH(G3,Listas!$A$2:$A$50,0)),0)) -> 4800 | AA3: Sí | AC3: EJEMPLO-gclid-123 | AD3: =IF(OR(LEFT(H3,4)="Meta",LEFT(H3,6)="Google"),IF(AG3=3,"Lead calificado",IF(OR(AG3=4,AG3=5),"Tasación/visita",IF(OR(AG3=6,AG3=7),"Captación/oferta",IF(AG3=8,"Cierre","")))),"") -> Lead calificado | AE3: No | AF3: EJEMPLO - borrá esta fila | AG3: =IF(R3="",0,IFERROR(MATCH(R3,Listas!$L$2:$L$50,0),0)) -> 3
A4: 3 | B4: 46302 | C4: Sofía | D4: Ruiz | E4: +54 9 11 5555-0303 | F4: sofia.ruiz@example.com | G4: Colega inmobiliario | H4: Meta Ads (formulario) | I4: Vendedores - Caballito | J4: Carrusel del barrio | K4: Caballito | R4: Descartado | T4: Es colega inmobiliario | W4: =IF(OR(V4="",AG4>=8),"",IF(V4<TODAY(),"Vencida",IF(V4=TODAY(),"Hoy",""))) | X4: =IF(A4="","",IF(COUNTIF(Seguimiento!$B$2:$B$5001,A4)=0,"",_xlfn.MAXIFS(Seguimiento!$A$2:$A$5001,Seguimiento!$B$2:$B$5001,A4))) | Y4: =IF(B4="","",TODAY()-B4) -> 3 | Z4: =IF(OR(O4="",G4=""),"",O4*IFERROR(INDEX(Listas!$B$2:$B$50,MATCH(G4,Listas!$A$2:$A$50,0)),0)) | AB4: 000000000000002 | AD4: =IF(OR(LEFT(H4,4)="Meta",LEFT(H4,6)="Google"),IF(AG4=3,"Lead calificado",IF(OR(AG4=4,AG4=5),"Tasación/visita",IF(OR(AG4=6,AG4=7),"Captación/oferta",IF(AG4=8,"Cierre","")))),"") | AF4: EJEMPLO - es agente, dejó datos para ofrecer un servicio. Borrá esta fila | AG4: =IF(R4="",0,IFERROR(MATCH(R4,Listas!$L$2:$L$50,0),0)) -> 10
W5: =IF(OR(V5="",AG5>=8),"",IF(V5<TODAY(),"Vencida",IF(V5=TODAY(),"Hoy",""))) | X5: =IF(A5="","",IF(COUNTIF(Seguimiento!$B$2:$B$5001,A5)=0,"",_xlfn.MAXIFS(Seguimiento!$A$2:$A$5001,Seguimiento!$B$2:$B$5001,A5))) | Y5: =IF(B5="","",TODAY()-B5) | Z5: =IF(OR(O5="",G5=""),"",O5*IFERROR(INDEX(Listas!$B$2:$B$50,MATCH(G5,Listas!$A$2:$A$50,0)),0)) | AD5: =IF(OR(LEFT(H5,4)="Meta",LEFT(H5,6)="Google"),IF(AG5=3,"Lead calificado",IF(OR(AG5=4,AG5=5),"Tasación/visita",IF(OR(AG5=6,AG5=7),"Captación/oferta",IF(AG5=8,"Cierre","")))),"") | AG5: =IF(R5="",0,IFERROR(MATCH(R5,Listas!$L$2:$L$50,0),0)) -> 0
W6: =IF(OR(V6="",AG6>=8),"",IF(V6<TODAY(),"Vencida",IF(V6=TODAY(),"Hoy",""))) | X6: =IF(A6="","",IF(COUNTIF(Seguimiento!$B$2:$B$5001,A6)=0,"",_xlfn.MAXIFS(Seguimiento!$A$2:$A$5001,Seguimiento!$B$2:$B$5001,A6))) | Y6: =IF(B6="","",TODAY()-B6) | Z6: =IF(OR(O6="",G6=""),"",O6*IFERROR(INDEX(Listas!$B$2:$B$50,MATCH(G6,Listas!$A$2:$A$50,0)),0)) | AD6: =IF(OR(LEFT(H6,4)="Meta",LEFT(H6,6)="Google"),IF(AG6=3,"Lead calificado",IF(OR(AG6=4,AG6=5),"Tasación/visita",IF(OR(AG6=6,AG6=7),"Captación/oferta",IF(AG6=8,"Cierre","")))),"") | AG6: =IF(R6="",0,IFERROR(MATCH(R6,Listas!$L$2:$L$50,0),0)) -> 0
W7: =IF(OR(V7="",AG7>=8),"",IF(V7<TODAY(),"Vencida",IF(V7=TODAY(),"Hoy",""))) | X7: =IF(A7="","",IF(COUNTIF(Seguimiento!$B$2:$B$5001,A7)=0,"",_xlfn.MAXIFS(Seguimiento!$A$2:$A$5001,Seguimiento!$B$2:$B$5001,A7))) | Y7: =IF(B7="","",TODAY()-B7) | Z7: =IF(OR(O7="",G7=""),"",O7*IFERROR(INDEX(Listas!$B$2:$B$50,MATCH(G7,Listas!$A$2:$A$50,0)),0)) | AD7: =IF(OR(LEFT(H7,4)="Meta",LEFT(H7,6)="Google"),IF(AG7=3,"Lead calificado",IF(OR(AG7=4,AG7=5),"Tasación/visita",IF(OR(AG7=6,AG7=7),"Captación/oferta",IF(AG7=8,"Cierre","")))),"") | AG7: =IF(R7="",0,IFERROR(MATCH(R7,Listas!$L$2:$L$50,0),0)) -> 0
W8: =IF(OR(V8="",AG8>=8),"",IF(V8<TODAY(),"Vencida",IF(V8=TODAY(),"Hoy",""))) | X8: =IF(A8="","",IF(COUNTIF(Seguimiento!$B$2:$B$5001,A8)=0,"",_xlfn.MAXIFS(Seguimiento!$A$2:$A$5001,Seguimiento!$B$2:$B$5001,A8))) | Y8: =IF(B8="","",TODAY()-B8) | Z8: =IF(OR(O8="",G8=""),"",O8*IFERROR(INDEX(Listas!$B$2:$B$50,MATCH(G8,Listas!$A$2:$A$50,0)),0)) | AD8: =IF(OR(LEFT(H8,4)="Meta",LEFT(H8,6)="Google"),IF(AG8=3,"Lead calificado",IF(OR(AG8=4,AG8=5),"Tasación/visita",IF(OR(AG8=6,AG8=7),"Captación/oferta",IF(AG8=8,"Cierre","")))),"") | AG8: =IF(R8="",0,IFERROR(MATCH(R8,Listas!$L$2:$L$50,0),0)) -> 0
W9: =IF(OR(V9="",AG9>=8),"",IF(V9<TODAY(),"Vencida",IF(V9=TODAY(),"Hoy",""))) | X9: =IF(A9="","",IF(COUNTIF(Seguimiento!$B$2:$B$5001,A9)=0,"",_xlfn.MAXIFS(Seguimiento!$A$2:$A$5001,Seguimiento!$B$2:$B$5001,A9))) | Y9: =IF(B9="","",TODAY()-B9) | Z9: =IF(OR(O9="",G9=""),"",O9*IFERROR(INDEX(Listas!$B$2:$B$50,MATCH(G9,Listas!$A$2:$A$50,0)),0)) | AD9: =IF(OR(LEFT(H9,4)="Meta",LEFT(H9,6)="Google"),IF(AG9=3,"Lead calificado",IF(OR(AG9=4,AG9=5),"Tasación/visita",IF(OR(AG9=6,AG9=7),"Captación/oferta",IF(AG9=8,"Cierre","")))),"") | AG9: =IF(R9="",0,IFERROR(MATCH(R9,Listas!$L$2:$L$50,0),0)) -> 0
W10: =IF(OR(V10="",AG10>=8),"",IF(V10<TODAY(),"Vencida",IF(V10=TODAY(),"Hoy",""))) | X10: =IF(A10="","",IF(COUNTIF(Seguimiento!$B$2:$B$5001,A10)=0,"",_xlfn.MAXIFS(Seguimiento!$A$2:$A$5001,Seguimiento!$B$2:$B$5001,A10))) | Y10: =IF(B10="","",TODAY()-B10) | Z10: =IF(OR(O10="",G10=""),"",O10*IFERROR(INDEX(Listas!$B$2:$B$50,MATCH(G10,Listas!$A$2:$A$50,0)),0)) | AD10: =IF(OR(LEFT(H10,4)="Meta",LEFT(H10,6)="Google"),IF(AG10=3,"Lead calificado",IF(OR(AG10=4,AG10=5),"Tasación/visita",IF(OR(AG10=6,AG10=7),"Captación/oferta",IF(AG10=8,"Cierre","")))),"") | AG10: =IF(R10="",0,IFERROR(MATCH(R10,Listas!$L$2:$L$50,0),0)) -> 0
W11: =IF(OR(V11="",AG11>=8),"",IF(V11<TODAY(),"Vencida",IF(V11=TODAY(),"Hoy",""))) | X11: =IF(A11="","",IF(COUNTIF(Seguimiento!$B$2:$B$5001,A11)=0,"",_xlfn.MAXIFS(Seguimiento!$A$2:$A$5001,Seguimiento!$B$2:$B$5001,A11))) | Y11: =IF(B11="","",TODAY()-B11) | Z11: =IF(OR(O11="",G11=""),"",O11*IFERROR(INDEX(Listas!$B$2:$B$50,MATCH(G11,Listas!$A$2:$A$50,0)),0)) | AD11: =IF(OR(LEFT(H11,4)="Meta",LEFT(H11,6)="Google"),IF(AG11=3,"Lead calificado",IF(OR(AG11=4,AG11=5),"Tasación/visita",IF(OR(AG11=6,AG11=7),"Captación/oferta",IF(AG11=8,"Cierre","")))),"") | AG11: =IF(R11="",0,IFERROR(MATCH(R11,Listas!$L$2:$L$50,0),0)) -> 0
W12: =IF(OR(V12="",AG12>=8),"",IF(V12<TODAY(),"Vencida",IF(V12=TODAY(),"Hoy",""))) | X12: =IF(A12="","",IF(COUNTIF(Seguimiento!$B$2:$B$5001,A12)=0,"",_xlfn.MAXIFS(Seguimiento!$A$2:$A$5001,Seguimiento!$B$2:$B$5001,A12))) | Y12: =IF(B12="","",TODAY()-B12) | Z12: =IF(OR(O12="",G12=""),"",O12*IFERROR(INDEX(Listas!$B$2:$B$50,MATCH(G12,Listas!$A$2:$A$50,0)),0)) | AD12: =IF(OR(LEFT(H12,4)="Meta",LEFT(H12,6)="Google"),IF(AG12=3,"Lead calificado",IF(OR(AG12=4,AG12=5),"Tasación/visita",IF(OR(AG12=6,AG12=7),"Captación/oferta",IF(AG12=8,"Cierre","")))),"") | AG12: =IF(R12="",0,IFERROR(MATCH(R12,Listas!$L$2:$L$50,0),0)) -> 0
W13: =IF(OR(V13="",AG13>=8),"",IF(V13<TODAY(),"Vencida",IF(V13=TODAY(),"Hoy",""))) | X13: =IF(A13="","",IF(COUNTIF(Seguimiento!$B$2:$B$5001,A13)=0,"",_xlfn.MAXIFS(Seguimiento!$A$2:$A$5001,Seguimiento!$B$2:$B$5001,A13))) | Y13: =IF(B13="","",TODAY()-B13) | Z13: =IF(OR(O13="",G13=""),"",O13*IFERROR(INDEX(Listas!$B$2:$B$50,MATCH(G13,Listas!$A$2:$A$50,0)),0)) | AD13: =IF(OR(LEFT(H13,4)="Meta",LEFT(H13,6)="Google"),IF(AG13=3,"Lead calificado",IF(OR(AG13=4,AG13=5),"Tasación/visita",IF(OR(AG13=6,AG13=7),"Captación/oferta",IF(AG13=8,"Cierre","")))),"") | AG13: =IF(R13="",0,IFERROR(MATCH(R13,Listas!$L$2:$L$50,0),0)) -> 0
W14: =IF(OR(V14="",AG14>=8),"",IF(V14<TODAY(),"Vencida",IF(V14=TODAY(),"Hoy",""))) | X14: =IF(A14="","",IF(COUNTIF(Seguimiento!$B$2:$B$5001,A14)=0,"",_xlfn.MAXIFS(Seguimiento!$A$2:$A$5001,Seguimiento!$B$2:$B$5001,A14))) | Y14: =IF(B14="","",TODAY()-B14) | Z14: =IF(OR(O14="",G14=""),"",O14*IFERROR(INDEX(Listas!$B$2:$B$50,MATCH(G14,Listas!$A$2:$A$50,0)),0)) | AD14: =IF(OR(LEFT(H14,4)="Meta",LEFT(H14,6)="Google"),IF(AG14=3,"Lead calificado",IF(OR(AG14=4,AG14=5),"Tasación/visita",IF(OR(AG14=6,AG14=7),"Captación/oferta",IF(AG14=8,"Cierre","")))),"") | AG14: =IF(R14="",0,IFERROR(MATCH(R14,Listas!$L$2:$L$50,0),0)) -> 0
W15: =IF(OR(V15="",AG15>=8),"",IF(V15<TODAY(),"Vencida",IF(V15=TODAY(),"Hoy",""))) | X15: =IF(A15="","",IF(COUNTIF(Seguimiento!$B$2:$B$5001,A15)=0,"",_xlfn.MAXIFS(Seguimiento!$A$2:$A$5001,Seguimiento!$B$2:$B$5001,A15))) | Y15: =IF(B15="","",TODAY()-B15) | Z15: =IF(OR(O15="",G15=""),"",O15*IFERROR(INDEX(Listas!$B$2:$B$50,MATCH(G15,Listas!$A$2:$A$50,0)),0)) | AD15: =IF(OR(LEFT(H15,4)="Meta",LEFT(H15,6)="Google"),IF(AG15=3,"Lead calificado",IF(OR(AG15=4,AG15=5),"Tasación/visita",IF(OR(AG15=6,AG15=7),"Captación/oferta",IF(AG15=8,"Cierre","")))),"") | AG15: =IF(R15="",0,IFERROR(MATCH(R15,Listas!$L$2:$L$50,0),0)) -> 0
W16: =IF(OR(V16="",AG16>=8),"",IF(V16<TODAY(),"Vencida",IF(V16=TODAY(),"Hoy",""))) | X16: =IF(A16="","",IF(COUNTIF(Seguimiento!$B$2:$B$5001,A16)=0,"",_xlfn.MAXIFS(Seguimiento!$A$2:$A$5001,Seguimiento!$B$2:$B$5001,A16))) | Y16: =IF(B16="","",TODAY()-B16) | Z16: =IF(OR(O16="",G16=""),"",O16*IFERROR(INDEX(Listas!$B$2:$B$50,MATCH(G16,Listas!$A$2:$A$50,0)),0)) | AD16: =IF(OR(LEFT(H16,4)="Meta",LEFT(H16,6)="Google"),IF(AG16=3,"Lead calificado",IF(OR(AG16=4,AG16=5),"Tasación/visita",IF(OR(AG16=6,AG16=7),"Captación/oferta",IF(AG16=8,"Cierre","")))),"") | AG16: =IF(R16="",0,IFERROR(MATCH(R16,Listas!$L$2:$L$50,0),0)) -> 0
... W2001: =IF(OR(V2001="",AG2001>=8),"",IF(V2001<TODAY(),"Vencida",IF(V2001=TODAY(),"Hoy",""))) | X2001: =IF(A2001="","",IF(COUNTIF(Seguimiento!$B$2:$B$5001,A2001)=0,"",_xlfn.MAXIFS(Seguimiento!$A$2:$A$5001,Seguimiento!$B$2:$B$5001,A2001))) | Y2001: =IF(B2001="","",TODAY()-B2001) | Z2001: =IF(OR(O2001="",G2001=""),"",O2001*IFERROR(INDEX(Listas!$B$2:$B$50,MATCH(G2001,Listas!$A$2:$A$50,0)),0)) | AD2001: =IF(OR(LEFT(H2001,4)="Meta",LEFT(H2001,6)="Google"),IF(AG2001=3,"Lead calificado",IF(OR(AG2001=4,AG2001=5),"Tasación/visita",IF(OR(AG2001=6,AG2001=7),"Captación/oferta",IF(AG2001=8,"Cierre","")))),"") | AG2001: =IF(R2001="",0,IFERROR(MATCH(R2001,Listas!$L$2:$L$50,0),0)) -> 0

Sheet Seguimiento
A1: Fecha | B1: N° lead | C1: Nombre (auto) | D1: Tipo (auto) | E1: Canal | F1: Qué pasó | G1: Próximo paso
A2: 46298 | B2: 1 | C2: =IF(B2="","",IFERROR(INDEX(Leads!$C$2:$C$5001,MATCH(B2,Leads!$A$2:$A$5001,0))&" "&INDEX(Leads!$D$2:$D$5001,MATCH(B2,Leads!$A$2:$A$5001,0)),"N° no encontrado")) -> Laura Gómez | D2: =IF(B2="","",IFERROR(INDEX(Leads!$G$2:$G$5001,MATCH(B2,Leads!$A$2:$A$5001,0)),"")) -> Vendedor | E2: WhatsApp | F2: Primer contacto. Quiere vender en 2027 pero tasar ya. | G2: Agendar tasación
A3: 46300 | B3: 1 | C3: =IF(B3="","",IFERROR(INDEX(Leads!$C$2:$C$5001,MATCH(B3,Leads!$A$2:$A$5001,0))&" "&INDEX(Leads!$D$2:$D$5001,MATCH(B3,Leads!$A$2:$A$5001,0)),"N° no encontrado")) -> Laura Gómez | D3: =IF(B3="","",IFERROR(INDEX(Leads!$G$2:$G$5001,MATCH(B3,Leads!$A$2:$A$5001,0)),"")) -> Vendedor | E3: Llamada | F3: Confirmó tasación para el 14/10. | G3: Ir a tasar
A4: 46302 | B4: 2 | C4: =IF(B4="","",IFERROR(INDEX(Leads!$C$2:$C$5001,MATCH(B4,Leads!$A$2:$A$5001,0))&" "&INDEX(Leads!$D$2:$D$5001,MATCH(B4,Leads!$A$2:$A$5001,0)),"N° no encontrado")) -> Martín Pérez | D4: =IF(B4="","",IFERROR(INDEX(Leads!$G$2:$G$5001,MATCH(B4,Leads!$A$2:$A$5001,0)),"")) -> Comprador | E4: WhatsApp | F4: Busca 2 ambientes con balcón, crédito preaprobado. | G4: Mandar opciones
C5: =IF(B5="","",IFERROR(INDEX(Leads!$C$2:$C$5001,MATCH(B5,Leads!$A$2:$A$5001,0))&" "&INDEX(Leads!$D$2:$D$5001,MATCH(B5,Leads!$A$2:$A$5001,0)),"N° no encontrado")) | D5: =IF(B5="","",IFERROR(INDEX(Leads!$G$2:$G$5001,MATCH(B5,Leads!$A$2:$A$5001,0)),""))
C6: =IF(B6="","",IFERROR(INDEX(Leads!$C$2:$C$5001,MATCH(B6,Leads!$A$2:$A$5001,0))&" "&INDEX(Leads!$D$2:$D$5001,MATCH(B6,Leads!$A$2:$A$5001,0)),"N° no encontrado")) | D6: =IF(B6="","",IFERROR(INDEX(Leads!$G$2:$G$5001,MATCH(B6,Leads!$A$2:$A$5001,0)),""))
C7: =IF(B7="","",IFERROR(INDEX(Leads!$C$2:$C$5001,MATCH(B7,Leads!$A$2:$A$5001,0))&" "&INDEX(Leads!$D$2:$D$5001,MATCH(B7,Leads!$A$2:$A$5001,0)),"N° no encontrado")) | D7: =IF(B7="","",IFERROR(INDEX(Leads!$G$2:$G$5001,MATCH(B7,Leads!$A$2:$A$5001,0)),""))
C8: =IF(B8="","",IFERROR(INDEX(Leads!$C$2:$C$5001,MATCH(B8,Leads!$A$2:$A$5001,0))&" "&INDEX(Leads!$D$2:$D$5001,MATCH(B8,Leads!$A$2:$A$5001,0)),"N° no encontrado")) | D8: =IF(B8="","",IFERROR(INDEX(Leads!$G$2:$G$5001,MATCH(B8,Leads!$A$2:$A$5001,0)),""))
C9: =IF(B9="","",IFERROR(INDEX(Leads!$C$2:$C$5001,MATCH(B9,Leads!$A$2:$A$5001,0))&" "&INDEX(Leads!$D$2:$D$5001,MATCH(B9,Leads!$A$2:$A$5001,0)),"N° no encontrado")) | D9: =IF(B9="","",IFERROR(INDEX(Leads!$G$2:$G$5001,MATCH(B9,Leads!$A$2:$A$5001,0)),""))
C10: =IF(B10="","",IFERROR(INDEX(Leads!$C$2:$C$5001,MATCH(B10,Leads!$A$2:$A$5001,0))&" "&INDEX(Leads!$D$2:$D$5001,MATCH(B10,Leads!$A$2:$A$5001,0)),"N° no encontrado")) | D10: =IF(B10="","",IFERROR(INDEX(Leads!$G$2:$G$5001,MATCH(B10,Leads!$A$2:$A$5001,0)),""))
C11: =IF(B11="","",IFERROR(INDEX(Leads!$C$2:$C$5001,MATCH(B11,Leads!$A$2:$A$5001,0))&" "&INDEX(Leads!$D$2:$D$5001,MATCH(B11,Leads!$A$2:$A$5001,0)),"N° no encontrado")) | D11: =IF(B11="","",IFERROR(INDEX(Leads!$G$2:$G$5001,MATCH(B11,Leads!$A$2:$A$5001,0)),""))
C12: =IF(B12="","",IFERROR(INDEX(Leads!$C$2:$C$5001,MATCH(B12,Leads!$A$2:$A$5001,0))&" "&INDEX(Leads!$D$2:$D$5001,MATCH(B12,Leads!$A$2:$A$5001,0)),"N° no encontrado")) | D12: =IF(B12="","",IFERROR(INDEX(Leads!$G$2:$G$5001,MATCH(B12,Leads!$A$2:$A$5001,0)),""))
C13: =IF(B13="","",IFERROR(INDEX(Leads!$C$2:$C$5001,MATCH(B13,Leads!$A$2:$A$5001,0))&" "&INDEX(Leads!$D$2:$D$5001,MATCH(B13,Leads!$A$2:$A$5001,0)),"N° no encontrado")) | D13: =IF(B13="","",IFERROR(INDEX(Leads!$G$2:$G$5001,MATCH(B13,Leads!$A$2:$A$5001,0)),""))
C14: =IF(B14="","",IFERROR(INDEX(Leads!$C$2:$C$5001,MATCH(B14,Leads!$A$2:$A$5001,0))&" "&INDEX(Leads!$D$2:$D$5001,MATCH(B14,Leads!$A$2:$A$5001,0)),"N° no encontrado")) | D14: =IF(B14="","",IFERROR(INDEX(Leads!$G$2:$G$5001,MATCH(B14,Leads!$A$2:$A$5001,0)),""))
C15: =IF(B15="","",IFERROR(INDEX(Leads!$C$2:$C$5001,MATCH(B15,Leads!$A$2:$A$5001,0))&" "&INDEX(Leads!$D$2:$D$5001,MATCH(B15,Leads!$A$2:$A$5001,0)),"N° no encontrado")) | D15: =IF(B15="","",IFERROR(INDEX(Leads!$G$2:$G$5001,MATCH(B15,Leads!$A$2:$A$5001,0)),""))
C16: =IF(B16="","",IFERROR(INDEX(Leads!$C$2:$C$5001,MATCH(B16,Leads!$A$2:$A$5001,0))&" "&INDEX(Leads!$D$2:$D$5001,MATCH(B16,Leads!$A$2:$A$5001,0)),"N° no encontrado")) | D16: =IF(B16="","",IFERROR(INDEX(Leads!$G$2:$G$5001,MATCH(B16,Leads!$A$2:$A$5001,0)),""))
... C1001: =IF(B1001="","",IFERROR(INDEX(Leads!$C$2:$C$5001,MATCH(B1001,Leads!$A$2:$A$5001,0))&" "&INDEX(Leads!$D$2:$D$5001,MATCH(B1001,Leads!$A$2:$A$5001,0)),"N° no encontrado")) | D1001: =IF(B1001="","",IFERROR(INDEX(Leads!$G$2:$G$5001,MATCH(B1001,Leads!$A$2:$A$5001,0)),""))

Sheet Listas
A1: Tipo de lead | B1: % comisión | D1: Origen | F1: Tipo de propiedad | H1: Plazo | J1: Forma de pago | L1: Etapa | N1: Temperatura | P1: Motivo pérdida / descarte | R1: Sí / No | T1: Canal de contacto | V1: Cómo usar esta hoja
A2: Vendedor | B2: 0.03 | D2: Meta Ads (formulario) | F2: Departamento | H2: Inmediato (0-3 meses) | J2: Contado | L2: 1. Nuevo | N2: Caliente | P2: Es colega inmobiliario | R2: Sí | T2: WhatsApp | V2: Para sumar una opción, escribila debajo de la última de su lista.
A3: Comprador | B3: 0.04 | D3: Meta Ads (WhatsApp/mensaje) | F3: Casa | H3: 3 a 6 meses | J3: Crédito hipotecario | L3: 2. Contactado | N3: Tibio | P3: Datos falsos | R3: No | T3: Llamada | V3: Los menús de Leads y Seguimiento la toman sola.
A4: Inversor | B4: 0.04 | D4: Google Ads (búsqueda) | F4: PH | H4: 6 a 12 meses | J4: Permuta | L4: 3. Calificado | N4: Frío | P4: No responde | T4: Email | V4: No dejes celdas vacías en el medio de una lista.
A5: Propietario (alquiler) | D5: Instagram orgánico | F5: Terreno | H5: Más de 12 meses | J5: Necesita vender primero | L5: 4. Tasación/visita agendada | P5: Solo curiosidad | T5: Reunión / tasación | V5: No cambies el orden de 'Etapa': el Panel usa la posición (1 a 8 = avance).
A6: Inquilino | D6: Facebook orgánico | F6: Local | H6: No sabe | J6: No sabe | L6: 5. Tasación/visita hecha | P6: Fuera de zona | T6: Visita
A7: Colega inmobiliario | D7: Portales (Zonaprop/Argenprop/ML) | F7: Oficina | L7: 6. Captada / oferta | P7: Precio fuera de mercado | T7: Mensaje Instagram/Facebook
A8: Spam / datos falsos | D8: Web propia | F8: Cochera | L8: 7. Reservado | P8: Eligió otra inmobiliaria | T8: Otro
D9: Referido | F9: Otro | L9: 8. Cerrado (ganado) | P9: Ya vendió / compró
D10: Cartel en propiedad | L10: Perdido | P10: Otro
D11: Base propia / ex clientes | L11: Descartado
D12: Otro
